Workbook

Sheet DRV-Prüfung
A5: Hartmut Ahting, Steuerberater, Heerstrasse 50, 60488 Frankfurt
A7: Franz Pfaff Innenausbau GmbH | E7: Rg-Datum: | G7: 42305
A8: Donnersbergstraße 25 | E8: Kunden-Nr.: | G8: 10113
E9: Rg-Nr.: | G9: 10113-2015-007
A10: 60528 Frankfurt | E10: IBAN: | F10: DE 13 50070024 0 4092862 00
E11: BIC (SWIFT): | F11: DEUTDEDBFRA
A16: Rechnung über Honorare
A19: Für die nachfolgend aufgeführten Leistungen erlaube ich mir nach der Steuerberatervergütungs-
A20: verordnung wie folgt abzurechnen:
A22: Leistung | E22: Gegenstands- | F22: Tabelle | G22: Geb.- | H22: Gebühr
A23: §§ | E23: wert | G23: satz
A24: 29 | B24: Teilnahme an der Prüfung der DRV für | E24: 80 | F24: Zeitgeb. | G24: 3 | H24: =+G24*E24
B25: 2011-2014
B26: - Vorbereitung der Prüfung und Zusammen-
B27: stellung vn Unterlagen vom 02.-15.10.2015
B28: - telefonische Klärung von Rüßckfragen durch den Prüfer
B29: am 19.10.2015
B30: - Abschluß der Prüfung durch Prüfung des Prüfberichts
B31: am 28.10.2015
A33: 16 | B33: Auslagenersatz für Post- und
B34: Telekommunikation | E34: =+H24*0.2 | H34: 20
E35: Zwischensumme | H35: =SUM(H24:H34)
E36: Umsatzsteuer 19% | H36: =+H35*0.19
E37: Rechnungsbetrag | H37: =SUM(H35:H36)
A39: Die Leistung wurde - sofern nicht anders angegeben - im Monat der Rechnungsstellung erbracht.
A40: Bitte überweisen Sie den Betrag ohne Abzüge auf die angegebene Bankverbindung.
A48: Steuernummer: 012 801 35159

Sheet JA 2014
A5: Hartmut Ahting, Steuerberater, Heerstrasse 50, 60488 Frankfurt
A7: Franz Pfaff Innenausbau GmbH | E7: Rg-Datum: | G7: 42270
A8: Donnersbergstraße 25 | E8: Kunden-Nr.: | H8: 10113
E9: Rg-Nr.: | G9: 10113-2015-008
A10: 60528 Frankfurt | E10: Leistungsdatum:* | G10: =+G7-1
E11: IBAN: | F11: DE 13 50070024 0 4092862 00
E12: BIC (SWIFT): | F12: DEUTDEDBFRA
A14: Rechnung über Honorare
A16: Für die nachfolgend aufgeführten Leistungen erlaube ich mir nach der Steuerberatervergütungs-
A17: verordnung wie folgt abzurechnen:
A19: Leistung | E19: Gegenstands- | F19: Tabelle | G19: Geb.- | H19: Gebühr
A20: §§ | E20: wert | G20: satz
A21: 35 | B21: Jahresabschluß | C21: 2014 | E21: =+(652336.86+247762.04)/2 | F21: B | G21: 23 | H21: =G21/10*701
A23: 35 | B23: Anhang | C23: =+C21 | E23: =+E21 | F23: B | G23: 6 | H23: =+H21/G21*G23
A25: 24 | B25: Umsatzsteuerjahreserklärung | C25: =+C23 | E25: =+(469613+197367+196088-1800)/10 | F25: A | G25: 2 | H25: =G25/10*1341
A27: 24 | B27: Gewerbesteuererklärung nach dem Gewerbe- | E27: =+E30 | F27: A | G27: 2 | H27: =G27/10*636
B28: ertrag für | C28: =+C23
A30: 24 | B30: Körperschaftsteuererklärung für | C30: =+C28 | E30: 16050 | F30: A | G30: 2 | H30: =G30/10*636
A32: 24 | B32: Erklärung zur gesonderten Ermittlung von Be- | E32: 8000 | F32: A | G32: 1 | H32: =G32/10*443
B33: steuerungsgrundlagen nach §§ 27 ff. KStG
B34: auf den 31.12. | C34: =+C30
A36: 27 | B36: Prüfung der Bescheide zur Körperschaftsteuer, | E36: 80 | F36: Zeitgeb. | G36: 0.5 | H36: =+G36*E36
B37: zum Gewerbesteuermeßbetrag und zur Feststellung
B38: körperschaftsteuerlicher Bemessungsgrundlagen 2012
B39: sowie zum körperschaftsteuerlichen und gewerbesteuerlichen
B40: Verlustvortrag 2013 am 23.10.2014
A42: 16 | B42: Auslagenersatz für Post- und | E42: =SUM(H21:H33)*0.15 | G42: 0 | H42: =+G42/10*E42
B43: Telekommunikation
A44: *sofern nicht separat anders angegeben | E44: Zwischensumme | H44: =SUM(H21:H43)
E45: Umsatzsteuer 19% | H45: =+H44*0.19
E46: Rechnungsbetrag | H46: =SUM(H44:H45)
A52: Steuernummer: 012 801 35159

Sheet Fibu III-2017
A5: Hartmut Ahting, Steuerberater, Heerstrasse 50, 60488 Frankfurt
A7: Franz Pfaff Innenausbau GmbH | E7: Rg-Datum: | G7: 43171
A8: Donnersbergstraße 25 | E8: Kunden-Nr.: | G8: 10113
E9: Rg-Nr.: | G9: 10113-2018-001
A10: 60528 Frankfurt | E10: IBAN: | F10: DE 13 50070024 0 4092862 00
E11: BIC (SWIFT): | F11: DEUTDEDBFRA
A16: Rechnung über Honorare
A19: Für die nachfolgend aufgeführten Leistungen erlaube ich mir nach der Steuerberatervergütungs-
A20: verordnung wie folgt abzurechnen:
A22: Leistung | E22: Gegenstands- | F22: Tabelle | G22: Geb.- | H22: Gebühr
A23: §§ | C23: am | E23: wert | G23: satz
A24: 33 | B24: Buchführung einschl. Kontieren der Belege | E24: 717000 | F24: C | G24: 4 | H24: =G24/10*581
B25: für 07/2017 am | C25: 42983
A27: 33 | B27: Buchführung einschl. Kontieren der Belege | E27: =+E24 | F27: C | G27: =+G24 | H27: =G27/10*581
B28: für 08/2017 am | C28: 43013
A30: 33 | B30: Buchführung einschl. Kontieren der Belege | E30: =+E27 | F30: C | G30: =+G27 | H30: =G30/10*581
B31: für 09/2017 am | C31: 43054
E34: Gesamt | H34: =SUM(H24:H33)
E35: USt 19% | H35: =+H34*0.19
E36: Rechnungsendbetrag | H36: =SUM(H34:H35)
A38: Bitte überweisen Sie den Betrag ohne Abzüge innerhalb von 14 Tagen auf das angegebene Konto.
A51: Steuernummer: 012 801 35159

Sheet Löhne IV-2017
A5: Hartmut Ahting, Steuerberater, Heerstrasse 50, 60488 Frankfurt
A7: Franz Pfaff Innenausbau GmbH | E7: Rg-Datum: | G7: 43172
A8: Donnersbergstraße 25 | E8: Kunden-Nr.: | G8: 10113 | L8: - LFZ-Anträge Mita | M8: 43034 | O8: 80 | P8: Zeitgeb. | Q8: 0.5 | R8: =+Q8*O8
E9: Rg-Nr.: | G9: 10113-2018-002
A10: 60528 Frankfurt | E10: IBAN: | F10: DE 13 50070024 0 4092862 00
E11: BIC: | F11: DEUTDEDBFRA
A15: Rechnung über Honorare
A17: Für die nachfolgend aufgeführten Leistungen erlaube ich mir nach der Steuerberatervergütungs-
A18: verordnung wie folgt abzurechnen:
A20: Leistung | E20: Gegenstands- | F20: Tabelle | G20: Arbeit- | H20: Gebühr
A21: §§ | C21: am/in: | E21: wert | G21: nehmer
A22: 34 | B22: Löhne/Gehälter 10/2017
B23: - Einrichten von Lohnkonten | C23: 43032 | E23: 9 | G23: 1 | H23: =+G23*E23
B24: (Ante Cesljar)
B25: - Lohnabrechnungen inkl.
B26: Sozialvers.-meldungen | C26: 43034 | E26: 15 | G26: 10 | H26: =+G26*E26
A28: 34 | B28: Löhne/Gehälter 11/2017
B29: - Lohnabrechnungen inkl.
B30: Sozialvers.-meldungen | C30: 43062 | E30: 15 | G30: 10 | H30: =+G30*E30
A32: 34 | B32: Löhne/Gehälter 12/2017
B33: - Lohnabrechnungen inkl.
B34: Sozialvers.-meldungen | C34: 43088 | E34: 15 | G34: 11 | H34: =+G34*E34
A36: 34 | B36: Hilfeleistung bei sonstigen Tätigkeiten im
B37: Zusammenhang mit dem Lohnsteuerabzug/der
B38: Lohnbuchführung
B39: - LFZ-Anträge Mita, Mario Perikic | C39: =+C30 | E39: 80 | F39: Zeitgeb. | G39: 0.5 | H39: =+G39*E39
A41: 16 | B41: Auslagenersatz für Post- und
B42: Telekommunikation | C42: IV/2017 | E42: =SUM(H22:H39)*0.2 | H42: =SUM(G26:G34)*1.3
E44: Gesamt | H44: =SUM(H22:H43)
E45: USt 19% | H45: =+H44*0.19
E46: Rechnungsendbetrag | H46: =SUM(H44:H45)
A48: Bitte überweisen Sie den Betrag ohne Abzüge innerhalb von 14 Tagen auf das angegebene Konto.
A55: Steuernummer: 012 801 35159

Sheet Fibu IV-2017
A5: Hartmut Ahting, Steuerberater, Heerstrasse 50, 60488 Frankfurt
A7: Franz Pfaff Innenausbau GmbH | E7: Rg-Datum: | G7: 43172
A8: Donnersbergstraße 25 | E8: Kunden-Nr.: | G8: 10113
E9: Rg-Nr.: | G9: 10113-2018-003
A10: 60528 Frankfurt | E10: IBAN: | F10: DE 13 50070024 0 4092862 00
E11: BIC: | F11: DEUTDEDBFRA
A16: Rechnung über Honorare
A19: Für die nachfolgend aufgeführten Leistungen erlaube ich mir nach der Steuerberatervergütungs-
A20: verordnung wie folgt abzurechnen:
A22: Leistung | E22: Gegenstands- | F22: Tabelle | G22: Geb.- | H22: Gebühr
A23: §§ | C23: am | E23: wert | G23: satz
A24: 33 | B24: Buchführung einschl. Kontieren der Belege | E24: 717000 | F24: C | G24: 4 | H24: =G24/10*581
B25: für 10/2017 am | C25: 43076
A27: 33 | B27: Buchführung einschl. Kontieren der Belege | E27: =+E24 | F27: C | G27: =+G24 | H27: =G27/10*581
B28: für 11/2017 am | C28: 43083
A30: 33 | B30: Buchführung einschl. Kontieren der Belege | E30: =+E27 | F30: C | G30: =+G27 | H30: =G30/10*581
B31: für 12/2017 am | C31: 43143
E34: Gesamt | H34: =SUM(H24:H33)
E35: USt 19% | H35: =+H34*0.19
E36: Rechnungsendbetrag | H36: =SUM(H34:H35)
A38: Bitte überweisen Sie den Betrag ohne Abzüge innerhalb von 14 Tagen auf das angegebene Konto.
A51: Steuernummer: 012 801 35159

Sheet Löhne I-2018
A5: Hartmut Ahting, Steuerberater, Heerstrasse 50, 60488 Frankfurt
A7: Franz Pfaff Innenausbau GmbH | E7: Rg-Datum: | G7: 43264
A8: Donnersbergstraße 25 | E8: Kunden-Nr.: | G8: 10113
E9: Rg-Nr.: | G9: 10113-2018-004
A10: 60528 Frankfurt | E10: IBAN: | F10: DE 13 50070024 0 4092862 00
E11: BIC: | F11: DEUTDEDBFRA
A15: Rechnung über Honorare
A17: Für die nachfolgend aufgeführten Leistungen erlaube ich mir nach der Steuerberatervergütungs-
A18: verordnung wie folgt abzurechnen:
A20: Leistung | E20: Gegenstands- | F20: Tabelle | G20: Arbeit- | H20: Gebühr
A21: §§ | C21: am/in: | E21: wert | G21: nehmer
A22: 34 | B22: Löhne/Gehälter 01/2018
B23: - Lohnabrechnungen inkl.
B24: Sozialvers.-meldungen | C24: 43124 | E24: 15 | G24: 9 | H24: =+G24*E24 | J24: X AN
A26: 34 | B26: Löhne/Gehälter 02/2018
B27: - Lohnabrechnungen inkl.
B28: Sozialvers.-meldungen | C28: 43153 | E28: 15 | G28: 9 | H28: =+G28*E28 | J28: x
A30: 34 | B30: Löhne/Gehälter 03/2018
B31: - Einrichten von Lohnkonten | C31: =+C28 | E31: 9 | G31: 1 | H31: =+G31*E31 | J31: x
B32: (Marko Skupnjak)
B33: - Lohnabrechnungen inkl.
B34: Sozialvers.-meldungen | C34: 43185 | E34: 15 | G34: 10 | H34: =+G34*E34 | J34: x
A40: 16 | B40: Auslagenersatz für Post- und
B41: Telekommunikation | C41: I/2018 | E41: =SUM(H22:H37)*0.2 | H41: =SUM(G24:G34)*1.3-1.3
E43: Gesamt | H43: =SUM(H22:H42)
E44: USt 19% | H44: =+H43*0.19
E45: Rechnungsendbetrag | H45: =SUM(H43:H44)
A47: Bitte überweisen Sie den Betrag ohne Abzüge innerhalb von 14 Tagen auf das angegebene Konto.
A54: Steuernummer: 012 801 35159

Sheet Fibu I-2018
A5: Hartmut Ahting, Steuerberater, Heerstrasse 50, 60488 Frankfurt
A7: Franz Pfaff Innenausbau GmbH | E7: Rg-Datum: | G7: 43264
A8: Donnersbergstraße 25 | E8: Kunden-Nr.: | G8: 10113
E9: Rg-Nr.: | G9: 10113-2018-005
A10: 60528 Frankfurt | E10: IBAN: | F10: DE 13 50070024 0 4092862 00
E11: BIC: | F11: DEUTDEDBFRA
A16: Rechnung über Honorare
A19: Für die nachfolgend aufgeführten Leistungen erlaube ich mir nach der Steuerberatervergütungs-
A20: verordnung wie folgt abzurechnen:
A22: Leistung | E22: Gegenstands- | F22: Tabelle | G22: Geb.- | H22: Gebühr
A23: §§ | C23: am | E23: wert | G23: satz
A24: 33 | B24: Buchführung einschl. Kontieren der Belege | E24: 1024760 | F24: C | G24: 2.5 | H24: =G24/10*761
B25: für 01/2018 am | C25: 43167
A27: 33 | B27: Buchführung einschl. Kontieren der Belege | E27: =+E24 | F27: C | G27: 2.5 | H27: =G27/10*761
B28: für 02/2018 am | C28: 43195
A30: 33 | B30: Buchführung einschl. Kontieren der Belege | E30: =+E27 | F30: C | G30: 3 | H30: =G30/10*761
B31: für 03/2018 am | C31: 43227
E34: Gesamt | H34: =SUM(H24:H33)
E35: USt 19% | H35: =+H34*0.19
E36: Rechnungsendbetrag | H36: =SUM(H34:H35)
A38: Bitte überweisen Sie den Betrag ohne Abzüge innerhalb von 14 Tagen auf das angegebene Konto.
A51: Steuernummer: 012 801 35159

Sheet Löhne II-2018
A5: Hartmut Ahting, Steuerberater, Heerstrasse 50, 60488 Frankfurt
A7: Franz Pfaff Innenausbau GmbH | E7: Rg-Datum: | G7: 43326
A8: Donnersbergstraße 25 | E8: Kunden-Nr.: | G8: 10113
E9: Rg-Nr.: | G9: 10113-2018-006
A10: 60528 Frankfurt | E10: IBAN: | F10: DE 13 50070024 0 4092862 00
E11: BIC: | F11: DEUTDEDBFRA
A14: Rechnung über Honorare
A16: Für die nachfolgend aufgeführten Leistungen erlaube ich mir nach der Steuerberatervergütungs-
A17: verordnung wie folgt abzurechnen:
A19: Leistung | E19: Gegenstands- | F19: Tabelle | G19: Arbeit- | H19: Gebühr
A20: §§ | C20: am/in: | E20: wert | G20: nehmer
A21: 34 | B21: Löhne/Gehälter 04/2018
B22: - Einrichten von Lohnkonten | C22: 43209 | E22: 9 | G22: 1 | H22: =+G22*E22
B23: (Zlatko Stjepanovic)
B24: - Lohnabrechnungen inkl.
B25: Sozialvers.-meldungen | C25: 43124 | E25: 15 | G25: 11 | H25: =+G25*E25
A27: 34 | B27: Löhne/Gehälter 05/2018
B28: - Lohnabrechnungen inkl.
B29: Sozialvers.-meldungen | C29: 43243 | E29: 15 | G29: 11 | H29: =+G29*E29
A31: 34 | B31: Löhne/Gehälter 06/2018
B32: - Lohnabrechnungen inkl.
B33: Sozialvers.-meldungen | C33: 43273 | E33: 15 | G33: 11 | H33: =+G33*E33
A35: 34 | B35: Hilfeleistung bei sonstigen Tätigkeiten im Zusammen- | E35: 80 | F35: Zeitgeb. | G35: 1 | H35: =+G35*E35
B36: hang mit dem Lohnsteuerabzug/der Lohnbuchführung
B37: - LFZ-Anträge Chmielowski | C37: 43209
B38: - LFZ-Anträge Mita, Chmielowski | C38: 43243
B39: - LFZ-Anträge Mario P. | C39: 43273
B40: - Unfallmeldung BG Mario P. | C40: 43216
A42: 16 | B42: Auslagenersatz für Post- und
B43: Telekommunikation | C43: II/2018 | E43: =SUM(H21:H34)*0.2 | H43: =SUM(G25:G33)*1.3
E45: Gesamt | H45: =SUM(H21:H44)
E46: USt 19% | H46: =+H45*0.19
E47: Rechnungsendbetrag | H47: =SUM(H45:H46)
A49: Bitte überweisen Sie den Betrag ohne Abzüge innerhalb von 14 Tagen auf das angegebene Konto.
A55: Steuernummer: 012 801 35159

Sheet Fibu II-2018
A5: Hartmut Ahting, Steuerberater, Heerstrasse 50, 60488 Frankfurt
A7: Franz Pfaff Innenausbau GmbH | E7: Rg-Datum: | G7: 43326
A8: Donnersbergstraße 25 | E8: Kunden-Nr.: | G8: 10113
E9: Rg-Nr.: | G9: 10113-2018-007
A10: 60528 Frankfurt | E10: IBAN: | F10: DE 13 50070024 0 4092862 00
E11: BIC: | F11: DEUTDEDBFRA
A16: Rechnung über Honorare
A19: Für die nachfolgend aufgeführten Leistungen erlaube ich mir nach der Steuerberatervergütungs-
A20: verordnung wie folgt abzurechnen:
A22: Leistung | E22: Gegenstands- | F22: Tabelle | G22: Geb.- | H22: Gebühr
A23: §§ | C23: am | E23: wert | G23: satz
A24: 33 | B24: Buchführung einschl. Kontieren der Belege | E24: 1024760 | F24: C | G24: 2.5 | H24: =G24/10*761
B25: für 04/2018 am | C25: 43242
A27: 33 | B27: Buchführung einschl. Kontieren der Belege | E27: =+E24 | F27: C | G27: 2.5 | H27: =G27/10*761
B28: für 05/2018 am | C28: 43286
A30: 33 | B30: Buchführung einschl. Kontieren der Belege | E30: =+E27 | F30: C | G30: 3 | H30: =G30/10*761
B31: für 06/2018 am | C31: 42948
E34: Gesamt | H34: =SUM(H24:H33)
E35: USt 19% | H35: =+H34*0.19
E36: Rechnungsendbetrag | H36: =SUM(H34:H35)
A38: Bitte überweisen Sie den Betrag ohne Abzüge innerhalb von 14 Tagen auf das angegebene Konto.
A51: Steuernummer: 012 801 35159

Sheet JA 2017
A5: Hartmut Ahting, Steuerberater, Heerstrasse 50, 60488 Frankfurt
A7: Franz Pfaff Innenausbau GmbH | E7: Rg-Datum: | G7: 43427
A8: Donnersbergstraße 25 | E8: Kunden-Nr.: | H8: 10113
E9: Rg-Nr.: | G9: 10113-2018-009
A10: 60528 Frankfurt | E10: Leistungsdatum:* | G10: =+G7
E11: IBAN: | F11: DE 13 50070024 0 4092862 00
E12: BIC: | F12: DEUTDEDBFRA
A15: Rechnung über Honorare
A18: Für die nachfolgend aufgeführten Leistungen erlaube ich mir nach der Steuerberatervergütungs-
A19: verordnung wie folgt abzurechnen:
A21: Leistung | E21: Gegenstands- | F21: Tabelle | G21: Geb.- | H21: Gebühr
A22: §§ | E22: wert | G22: satz
A23: 35 | B23: Jahresabschluß | C23: 2017 | E23: =+(J23+K23)/2 | F23: B | G23: 24 | H23: =G23/10*734 | J23: 303024.8 | K23: =701654.76+7326.77
A25: 35 | B25: Steuerbilanz und -GuV | C25: =+C23 | E25: =+(J25+K25)/2 | F25: B | G25: 7.5 | H25: =G25/10*734 | J25: 283688.8 | K25: =701654.76+15219.77
A27: 24 | B27: Umsatzsteuerjahreserklärung | C27: =+C25 | E27: =+(708154+96026+4323)/10 | F27: A | G27: 2 | H27: =G27/10*1341
A29: 24 | B29: Gewerbesteuererklärung nach dem Gewerbe- | E29: 8000 | F29: A | G29: 2 | H29: =G29/10*443
B30: ertrag für | C30: =+C23
A32: 24 | B32: Körperschaftsteuererklärung für | C32: =+C30 | E32: 16000 | F32: A | G32: 2 | H32: =G32/10*594
A34: 24 | B34: Erklärung zur gesonderten Ermittlung von Be- | E34: 8000 | F34: A | G34: 1 | H34: =G34/10*443
B35: steuerungsgrundlagen nach §§ 27 ff. KStG
B36: auf den 31.12. | C36: =+C32
A38: 27 | B38: Prüfung der Bescheide zur Körperschaftsteuer, | E38: 80 | F38: Zeitgeb. | G38: 0.5 | H38: =+G38*E38
B39: zum Gewerbesteuermeßbetrag und zur Feststellung
B40: körperschaftsteuerlicher Bemessungsgrundlagen 2016
B41: am 06.09.2017
A43: 16 | B43: Auslagenersatz für Post- und | E43: =SUM(H23:H35)*0.15 | G43: 0 | H43: 20
B44: Telekommunikation
A45: *sofern nicht separat anders angegeben | E45: Zwischensumme | H45: =SUM(H23:H44)
E46: Umsatzsteuer 19% | H46: =+H45*0.19
E47: Rechnungsbetrag | H47: =SUM(H45:H46)
A52: Steuernummer: 012 801 35159

Sheet Löhne III-2018
A5: Hartmut Ahting, Steuerberater, Heerstrasse 50, 60488 Frankfurt
A7: Franz Pfaff Innenausbau GmbH | E7: Rg-Datum: | G7: 43390
A8: Donnersbergstraße 25 | E8: Kunden-Nr.: | G8: 10113
E9: Rg-Nr.: | G9: 10113-2018-008
A10: 60528 Frankfurt | E10: IBAN: | F10: DE 13 50070024 0 4092862 00
E11: BIC: | F11: DEUTDEDBFRA
A14: Rechnung über Honorare
A16: Für die nachfolgend aufgeführten Leistungen erlaube ich mir nach der Steuerberatervergütungs-
A17: verordnung wie folgt abzurechnen:
A19: Leistung | E19: Gegenstands- | F19: Tabelle | G19: Arbeit- | H19: Gebühr
A20: §§ | C20: am/in: | E20: wert | G20: nehmer
A21: 34 | B21: Löhne/Gehälter 07/2018
B22: - Lohnabrechnungen inkl.
B23: Sozialvers.-meldungen | C23: 43293 | E23: 15 | G23: 11 | H23: =+G23*E23
A25: 34 | B25: Löhne/Gehälter 08/2018
B26: - Einrichten von Lohnkonten | C26: 43335 | E26: 9 | G26: 1 | H26: =+G26*E26
B27: (Marcin Zatylny) | C27: 3
B28: - Lohnabrechnungen inkl.
B29: Sozialvers.-meldungen | C29: 43339 | E29: 15 | G29: 12 | H29: =+G29*E29
A31: 34 | B31: Löhne/Gehälter 09/2018
B32: - Einrichten von Lohnkonten | C32: 43335 | E32: 9 | G32: 1 | H32: =+G32*E32
B33: (Nikola Vincetic) | C33: 3
B34: - Lohnabrechnungen inkl.
B35: Sozialvers.-meldungen | C35: 43367 | E35: 15 | G35: 13 | H35: =+G35*E35
A37: 34 | B37: Hilfeleistung bei sonstigen Tätigkeiten im Zusammen- | E37: 80 | F37: Zeitgeb. | G37: 1 | H37: =+G37*E37
B38: hang mit dem Lohnsteuerabzug/der Lohnbuchführung
B39: - LFZ-Anträge Skupnijak | C39: =+C23
B40: =+B39 | C40: =+C29
B41: =+B40 | C41: =+C35
A43: 16 | B43: Auslagenersatz für Post- und
B44: Telekommunikation | C44: III/2018 | E44: =SUM(H21:H36)*0.2 | H44: =(G23+G29+G35)*1.3
E46: Gesamt | H46: =SUM(H21:H45)
E47: USt 19% | H47: =+H46*0.19
E48: Rechnungsendbetrag | H48: =SUM(H46:H47)
A50: Bitte überweisen Sie den Betrag ohne Abzüge innerhalb von 14 Tagen auf das angegebene Konto.
A55: Steuernummer: 012 801 35159

Sheet Fibu III-2018
A5: Hartmut Ahting, Steuerberater, Heerstrasse 50, 60488 Frankfurt
A7: Franz Pfaff Innenausbau GmbH | E7: Rg-Datum: | G7: 43427
A8: Donnersbergstraße 25 | E8: Kunden-Nr.: | G8: 10113
E9: Rg-Nr.: | G9: 10113-2018-010
A10: 60528 Frankfurt | E10: IBAN: | F10: DE 13 50070024 0 4092862 00
E11: BIC: | F11: DEUTDEDBFRA
A16: Rechnung über Honorare
A19: Für die nachfolgend aufgeführten Leistungen erlaube ich mir nach der Steuerberatervergütungs-
A20: verordnung wie folgt abzurechnen:
A22: Leistung | E22: Gegenstands- | F22: Tabelle | G22: Geb.- | H22: Gebühr
A23: §§ | C23: am | E23: wert | G23: satz
A24: 33 | B24: Buchführung einschl. Kontieren der Belege | E24: 1024760 | F24: C | G24: 2.5 | H24: =G24/10*761
B25: für 07/2018 am | C25: 43360
A27: 33 | B27: Buchführung einschl. Kontieren der Belege | E27: =+E24 | F27: C | G27: 2.5 | H27: =G27/10*761
B28: für 08/2018 am | C28: 43361
A30: 33 | B30: Buchführung einschl. Kontieren der Belege | E30: =+E27 | F30: C | G30: 2.5 | H30: =G30/10*761
B31: für 09/2018 am | C31: 43416
E34: Gesamt | H34: =SUM(H24:H33)
E35: USt 19% | H35: =+H34*0.19
E36: Rechnungsendbetrag | H36: =SUM(H34:H35)
A38: Bitte überweisen Sie den Betrag ohne Abzüge innerhalb von 14 Tagen auf das angegebene Konto.
A51: Steuernummer: 012 801 35159

Sheet Löhne IV-2018 
A5: Hartmut Ahting, Steuerberater, Heerstrasse 50, 60488 Frankfurt
A7: Franz Pfaff Innenausbau GmbH | E7: Rg-Datum: | G7: 43528
A8: Donnersbergstraße 25 | E8: Kunden-Nr.: | G8: 10113 | L8: - Einrichten von Lohnkonten | M8: 43335 | O8: 9 | Q8: 1 | R8: =+Q8*O8
E9: Rg-Nr.: | G9: 10113-2019-001 | L9: (Nikola Vincetic) | M9: 3
A10: 60528 Frankfurt | E10: IBAN: | F10: DE 13 50070024 0 4092862 00
E11: BIC: | F11: DEUTDEDBFRA
A14: Rechnung über Honorare
A16: Für die nachfolgend aufgeführten Leistungen erlaube ich mir nach der Steuerberatervergütungs-
A17: verordnung wie folgt abzurechnen:
A19: Leistung | E19: Gegenstands- | F19: Tabelle | G19: Arbeit- | H19: Gebühr
A20: §§ | C20: am/in: | E20: wert | G20: nehmer
A21: 34 | B21: Löhne/Gehälter 10/2018
B22: - Lohnabrechnungen inkl.
B23: Sozialvers.-meldungen | C23: 43396 | E23: 15 | G23: 11 | H23: =+G23*E23
A25: 34 | B25: Löhne/Gehälter 11/2018
B26: - Einrichten von Lohnkonten | C26: 43426 | E26: 9 | G26: 1 | H26: =+G26*E26
B27: (Samual Perikic)
B28: - Lohnabrechnungen inkl.
B29: Sozialvers.-meldungen | C29: 43430 | E29: 15 | G29: 12 | H29: =+G29*E29
A31: 34 | B31: Löhne/Gehälter 12/2018
B32: - Lohnabrechnungen inkl.
B33: Sozialvers.-meldungen | C33: 43454 | E33: 15 | G33: 11 | H33: =+G33*E33
A35: 34 | B35: Hilfeleistung bei sonstigen Tätigkeiten im Zusammen- | E35: 80 | F35: Zeitgeb. | G35: 1 | H35: =+G35*E35
B36: hang mit dem Lohnsteuerabzug/der Lohnbuchführung
B37: - LFZ-Anträge Chmielowski | C37: 43396
B38: - LFZ-Anträge Chmieowski,Münster, | C38: 43430
B39: Stjepanowicz
B40: =+B38 | C40: =+C33
A42: 16 | B42: Auslagenersatz für Post- und
B43: Telekommunikation | C43: IV/2018 | E43: =SUM(H21:H34)*0.2 | H43: =(G23+G29+G33)*1.3
E45: Gesamt | H45: =SUM(H21:H44)
E46: USt 19% | H46: =+H45*0.19
E47: Rechnungsendbetrag | H47: =SUM(H45:H46)
A49: Bitte überweisen Sie den Betrag ohne Abzüge innerhalb von 14 Tagen auf das angegebene Konto.
A55: Steuernummer: 012 801 35159

Sheet DRV 15-18
A5: Hartmut Ahting, Steuerberater, Heerstrasse 50, 60488 Frankfurt
A7: Franz Pfaff Innenausbau GmbH | E7: Rg-Datum: | G7: 43528
A8: Donnersbergstraße 25 | E8: Kunden-Nr.: | G8: 10113
E9: Rg-Nr.: | G9: 10113-2019-002
A10: 60528 Frankfurt | E10: IBAN: | F10: DE 13 50070024 0 4092862 00
E11: BIC: | F11: DEUTDEDBFRA
A16: Rechnung über Honorare
A19: Für die nachfolgend aufgeführten Leistungen erlaube ich mir nach der Steuerberatervergütungs-
A20: verordnung wie folgt abzurechnen:
A22: Leistung | E22: Gegenstands- | F22: Tabelle | G22: Geb.- | H22: Gebühr
A23: §§ | C23: am | E23: wert | G23: satz
A24: 29 | B24: Teilnahme an der Prüfung der DRV für | E24: 100 | F24: Zeitgeb. | G24: 3 | H24: =+G24*E24
B25: 2015-2018
B26: - Vorbereitung der Prüfung und Zusammen-
B27: stellung von Unterlagen vom 17.01.-22.01.2019
B28: - Prüfungstermin am 05.02.2019,
B29: - Abschluß der Prüfung durch Prüfung des Prüfberichts
B30: am 20.02.2019
A32: 16 | B32: Auslagenersatz für Post- und
B33: Telekommunikation | E33: =+H24*0.2 | H33: 5
E34: Zwischensumme | H34: =SUM(H24:H33)
E35: Umsatzsteuer 19% | H35: =+H34*0.19
E36: Rechnungsbetrag | H36: =SUM(H34:H35)
A38: Bitte überweisen Sie den Betrag ohne Abzüge innerhalb von 14 Tagen auf das angegebene Konto.
A49: Steuernummer: 012 801 35159

Sheet Fibu IV-2018
A5: Hartmut Ahting, Steuerberater, Heerstrasse 50, 60488 Frankfurt
A7: Franz Pfaff Innenausbau GmbH | E7: Rg-Datum: | G7: 43528
A8: Donnersbergstraße 25 | E8: Kunden-Nr.: | G8: 10113
E9: Rg-Nr.: | G9: 10113-201--003
A10: 60528 Frankfurt | E10: IBAN: | F10: DE 13 50070024 0 4092862 00
E11: BIC: | F11: DEUTDEDBFRA
A16: Rechnung über Honorare
A19: Für die nachfolgend aufgeführten Leistungen erlaube ich mir nach der Steuerberatervergütungs-
A20: verordnung wie folgt abzurechnen:
A22: Leistung | E22: Gegenstands- | F22: Tabelle | G22: Geb.- | H22: Gebühr
A23: §§ | C23: am | E23: wert | G23: satz
A24: 33 | B24: Buchführung einschl. Kontieren der Belege | E24: 1068339.2 | F24: C | G24: 2.5 | H24: =G24/10*791
B25: für 10/2018 am | C25: 43441
A27: 33 | B27: Buchführung einschl. Kontieren der Belege | E27: =+E24 | F27: C | G27: 2.5 | H27: =G27/10*791
B28: für 11/2018 am | C28: 43448
A30: 33 | B30: Buchführung einschl. Kontieren der Belege | E30: =+E27 | F30: C | G30: 3 | H30: =G30/10*791
B31: für 12/2018 am | C31: 43508
E34: Gesamt | H34: =SUM(H24:H33)
E35: USt 19% | H35: =+H34*0.19
E36: Rechnungsendbetrag | H36: =SUM(H34:H35)
A38: Bitte überweisen Sie den Betrag ohne Abzüge innerhalb von 14 Tagen auf das angegebene Konto.
A51: Steuernummer: 012 801 35159

Sheet Löhne I-2019
A5: Hartmut Ahting, Steuerberater, Heerstrasse 50, 60488 Frankfurt
A7: Franz Pfaff Innenausbau GmbH | E7: Rg-Datum: | G7: 43628
A8: Donnersbergstraße 25 | E8: Kunden-Nr.: | G8: 10113
E9: Rg-Nr.: | G9: 10113-2019-004
A10: 60528 Frankfurt | E10: IBAN: | F10: DE 13 50070024 0 4092862 00
E11: BIC: | F11: DEUTDEDBFRA
A15: Rechnung über Honorare
A17: Für die nachfolgend aufgeführten Leistungen erlaube ich mir nach der Steuerberatervergütungs-
A18: verordnung wie folgt abzurechnen:
A20: Leistung | E20: Gegenstands- | F20: Tabelle | G20: Arbeit- | H20: Gebühr
A21: §§ | C21: am/in: | E21: wert | G21: nehmer
A22: 34 | B22: Löhne/Gehälter 01/2019
B23: - Lohnabrechnungen inkl.
B24: Sozialvers.-meldungen | C24: 43489 | E24: 15 | G24: 11 | H24: =+G24*E24
A26: 34 | B26: Löhne/Gehälter 02/2019
B27: - Einrichten von Lohnkonten | C27: =+C30 | E27: 9 | G27: 1 | H27: =+G27*E27
B28: (Zedenko Pejalovic)
B29: - Lohnabrechnungen inkl.
B30: Sozialvers.-meldungen | C30: 43518 | E30: 15 | G30: 12 | H30: =+G30*E30
A32: 34 | B32: Löhne/Gehälter 03/2019
B33: - Lohnabrechnungen inkl.
B34: Sozialvers.-meldungen | C34: 43549 | E34: 15 | G34: 12 | H34: =+G34*E34
A40: 16 | B40: Auslagenersatz für Post- und
B41: Telekommunikation | C41: I/2019 | E41: =SUM(H22:H37)*0.2 | H41: =SUM(G24:G34)*1.3-1.3
E43: Gesamt | H43: =SUM(H22:H42)
E44: USt 19% | H44: =+H43*0.19
E45: Rechnungsendbetrag | H45: =SUM(H43:H44)
A47: Bitte überweisen Sie den Betrag ohne Abzüge innerhalb von 14 Tagen auf das angegebene Konto.
A54: Steuernummer: 012 801 35159

Sheet Fibu I-2019
A5: Hartmut Ahting, Steuerberater, Heerstrasse 50, 60488 Frankfurt
A7: Franz Pfaff Innenausbau GmbH | E7: Rg-Datum: | G7: 43628
A8: Donnersbergstraße 25 | E8: Kunden-Nr.: | G8: 10113
E9: Rg-Nr.: | G9: 10113-2019-005
A10: 60528 Frankfurt | E10: IBAN: | F10: DE 13 50070024 0 4092862 00
E11: BIC: | F11: DEUTDEDBFRA
A16: Rechnung über Honorare
A19: Für die nachfolgend aufgeführten Leistungen erlaube ich mir nach der Steuerberatervergütungs-
A20: verordnung wie folgt abzurechnen:
A22: Leistung | E22: Gegenstands- | F22: Tabelle | G22: Geb.- | H22: Gebühr
A23: §§ | C23: am | E23: wert | G23: satz
A24: 33 | B24: Buchführung einschl. Kontieren der Belege | E24: 1036500 | F24: C | G24: 3 | H24: =G24/10*761
B25: für 01/2019 am | C25: 43532
A27: 33 | B27: Buchführung einschl. Kontieren der Belege | E27: =+E24 | F27: C | G27: 3 | H27: =G27/10*761
B28: für 02/2019 am | C28: 43563
A30: 33 | B30: Buchführung einschl. Kontieren der Belege | E30: =+E27 | F30: C | G30: 3 | H30: =G30/10*761
B31: für 03/2019 am | C31: 43592
E34: Gesamt | H34: =SUM(H24:H33)
E35: USt 19% | H35: =+H34*0.19
E36: Rechnungsendbetrag | H36: =SUM(H34:H35)
A38: Bitte überweisen Sie den Betrag ohne Abzüge innerhalb von 14 Tagen auf das angegebene Konto.
A51: Steuernummer: 012 801 35159

Sheet Löhne II-2019
L2: - Einrichten von Lohnkonten | M2: 43579 | O2: 9 | Q2: 1 | R2: =+Q2*O2
L3: (Zlatko Stjepanovic)
A5: Hartmut Ahting, Steuerberater, Heerstrasse 50, 60488 Frankfurt
A7: Franz Pfaff Innenausbau GmbH | E7: Rg-Datum: | G7: 43710
A8: Donnersbergstraße 25 | E8: Kunden-Nr.: | G8: 10113
E9: Rg-Nr.: | G9: 10113-2019-006
A10: 60528 Frankfurt | E10: IBAN: | F10: DE 13 50070024 0 4092862 00
E11: BIC: | F11: DEUTDEDBFRA
A15: Rechnung über Honorare
A18: Für die nachfolgend aufgeführten Leistungen erlaube ich mir nach der Steuerberatervergütungs-
A19: verordnung wie folgt abzurechnen:
A21: Leistung | E21: Gegenstands- | F21: Tabelle | G21: Arbeit- | H21: Gebühr | L21: - LFZ-Anträge Chmielowski
A22: §§ | C22: am/in: | E22: wert | G22: nehmer | L22: - LFZ-Anträge Mita, Chmielowski
A23: 34 | B23: Löhne/Gehälter 04/2019
B24: - Lohnabrechnungen inkl.
B25: Sozialvers.-meldungen | C25: 43579 | E25: 15 | G25: 13 | H25: =+G25*E25
A27: 34 | B27: Löhne/Gehälter 05/2019
B28: - Lohnabrechnungen inkl.
B29: Sozialvers.-meldungen | C29: 43608 | E29: 15 | G29: 13 | H29: =+G29*E29
A31: 34 | B31: Löhne/Gehälter 06/2019
B32: - Lohnabrechnungen inkl.
B33: Sozialvers.-meldungen | C33: 43640 | E33: 15 | G33: 13 | H33: =+G33*E33
A35: 34 | B35: Hilfeleistung bei sonstigen Tätigkeiten im Zusammen- | E35: 80 | F35: Zeitgeb. | G35: 1 | H35: =+G35*E35
B36: hang mit dem Lohnsteuerabzug/der Lohnbuchführung
B37: - LFZ-Anträge Mario P., Orsolic, | C37: 43564
B38: - LFZ-Anträge Mario P., Orsolic, | C38: 43601
B39: - LFZ-Anträge Pejakovic | C39: =+C33
A41: 16 | B41: Auslagenersatz für Post- und
B42: Telekommunikation | C42: II/2019 | E42: =SUM(H23:H34)*0.2 | H42: =SUM(G25:G33)*1.3
E44: Gesamt | H44: =SUM(H23:H43)
E45: USt 19% | H45: =+H44*0.19
E46: Rechnungsendbetrag | H46: =SUM(H44:H45)
A48: Bitte überweisen Sie den Betrag ohne Abzüge innerhalb von 14 Tagen auf das angegebene Konto.
A55: Steuernummer: 012 801 35159

Sheet Fibu II-2019
A5: Hartmut Ahting, Steuerberater, Heerstrasse 50, 60488 Frankfurt
A7: Franz Pfaff Innenausbau GmbH | E7: Rg-Datum: | G7: 43710
A8: Donnersbergstraße 25 | E8: Kunden-Nr.: | G8: 10113
E9: Rg-Nr.: | G9: 10113-2019-007
A10: 60528 Frankfurt | E10: IBAN: | F10: DE 13 50070024 0 4092862 00
E11: BIC: | F11: DEUTDEDBFRA
A16: Rechnung über Honorare
A19: Für die nachfolgend aufgeführten Leistungen erlaube ich mir nach der Steuerberatervergütungs-
A20: verordnung wie folgt abzurechnen:
A22: Leistung | E22: Gegenstands- | F22: Tabelle | G22: Geb.- | H22: Gebühr
A23: §§ | C23: am | E23: wert | G23: satz
A24: 33 | B24: Buchführung einschl. Kontieren der Belege | E24: 1036000 | F24: C | G24: 2.5 | H24: =G24/10*761
B25: für 04/2019 am | C25: 43627
A27: 33 | B27: Buchführung einschl. Kontieren der Belege | E27: =+E24 | F27: C | G27: 2.5 | H27: =G27/10*761
B28: für 05/2019 am | C28: 43654
A30: 33 | B30: Buchführung einschl. Kontieren der Belege | E30: =+E27 | F30: C | G30: 2.5 | H30: =G30/10*761
B31: für 06/2019 am | C31: 43685
E34: Gesamt | H34: =SUM(H24:H33)
E35: USt 19% | H35: =+H34*0.19
E36: Rechnungsendbetrag | H36: =SUM(H34:H35)
A38: Bitte überweisen Sie den Betrag ohne Abzüge innerhalb von 14 Tagen auf das angegebene Konto.
A51: Steuernummer: 012 801 35159

Sheet Löhne III-2019
A5: Hartmut Ahting, Steuerberater, Heerstrasse 50, 60488 Frankfurt
A7: Franz Pfaff Innenausbau GmbH | E7: Rg-Datum: | G7: 43761
A8: Donnersbergstraße 25 | E8: Kunden-Nr.: | G8: 10113
E9: Rg-Nr.: | G9: 10113-2019-008
A10: 60528 Frankfurt | E10: IBAN: | F10: DE 13 50070024 0 4092862 00
E11: BIC: | F11: DEUTDEDBFRA
A15: Rechnung über Honorare
A18: Für die nachfolgend aufgeführten Leistungen erlaube ich mir nach der Steuerberatervergütungs-
A19: verordnung wie folgt abzurechnen:
A21: Leistung | E21: Gegenstands- | F21: Tabelle | G21: Arbeit- | H21: Gebühr
A22: §§ | C22: am/in: | E22: wert | G22: nehmer
A23: 34 | B23: Löhne/Gehälter 07/2019
B24: - Lohnabrechnungen inkl.
B25: Sozialvers.-meldungen | C25: 43670 | E25: 15 | G25: 13 | H25: =+G25*E25
A27: 34 | B27: Löhne/Gehälter 08/2019
B28: - Einrichten von Lohnkonten | E28: 9 | G28: 1 | H28: =+G28*E28
B29: (Bilic) | C29: 43678
B30: - Lohnabrechnungen inkl.
B31: Sozialvers.-meldungen | C31: 43698 | E31: 15 | G31: 14 | H31: =+G31*E31
A33: 34 | B33: Löhne/Gehälter 09/2019
B34: - Lohnabrechnungen inkl.
B35: Sozialvers.-meldungen | C35: 43366 | E35: 15 | G35: 13 | H35: =+G35*E35
A37: 34 | B37: Hilfeleistung bei sonstigen Tätigkeiten im Zusammen- | E37: 80 | F37: Zeitgeb. | G37: 0 | H37: =+G37*E37
B38: hang mit dem Lohnsteuerabzug/der Lohnbuchführung
B39: - LFZ-Anträge Mario Perikic | C39: =+C25
A41: 16 | B41: Auslagenersatz für Post- und
B42: Telekommunikation | C42: III/2019 | E42: =SUM(H23:H36)*0.2 | H42: =(G25+G31+G35)*1.3
E44: Gesamt | H44: =SUM(H23:H43)
E45: USt 19% | H45: =+H44*0.19
E46: Rechnungsendbetrag | H46: =SUM(H44:H45)
A48: Bitte überweisen Sie den Betrag ohne Abzüge innerhalb von 14 Tagen auf das angegebene Konto.
A54: Steuernummer: 012 801 35159

Sheet Fibu III-2019
A5: Hartmut Ahting, Steuerberater, Heerstrasse 50, 60488 Frankfurt
A7: Franz Pfaff Innenausbau GmbH | E7: Rg-Datum: | G7: 43787
A8: Donnersbergstraße 25 | E8: Kunden-Nr.: | G8: 10113
E9: Rg-Nr.: | G9: 10113-2019-009
A10: 60528 Frankfurt | E10: IBAN: | F10: DE 13 50070024 0 4092862 00
E11: BIC: | F11: DEUTDEDBFRA
A16: Rechnung über Honorare
A19: Für die nachfolgend aufgeführten Leistungen erlaube ich mir nach der Steuerberatervergütungs-
A20: verordnung wie folgt abzurechnen:
A22: Leistung | E22: Gegenstands- | F22: Tabelle | G22: Geb.- | H22: Gebühr
A23: §§ | C23: am | E23: wert | G23: satz
A24: 33 | B24: Buchführung einschl. Kontieren der Belege | E24: 1036000 | F24: C | G24: 2.5 | H24: =G24/10*761
B25: für 07/2019 am | C25: 43717
A27: 33 | B27: Buchführung einschl. Kontieren der Belege | E27: =+E24 | F27: C | G27: 2.5 | H27: =G27/10*761
B28: für 08/2019 am | C28: 43733
A30: 33 | B30: Buchführung einschl. Kontieren der Belege | E30: =+E27 | F30: C | G30: 2.5 | H30: =G30/10*761
B31: für 09/2019 am | C31: 43780
E34: Gesamt | H34: =SUM(H24:H33)
E35: USt 19% | H35: =+H34*0.19
E36: Rechnungsendbetrag | H36: =SUM(H34:H35)
A38: Bitte überweisen Sie den Betrag ohne Abzüge innerhalb von 14 Tagen auf das angegebene Konto.
A51: Steuernummer: 012 801 35159

Sheet JA 2018
A5: Hartmut Ahting, Steuerberater, Heerstrasse 50, 60488 Frankfurt
A7: Franz Pfaff Innenausbau GmbH | E7: Rg-Datum: | G7: 43808
A8: Donnersbergstraße 25 | E8: Kunden-Nr.: | H8: 10113
E9: Rg-Nr.: | G9: 10113-2019-010 | K9: 27 | L9: Prüfung der Bescheide zur Körperschaftsteuer, | O9: 80 | P9: Zeitgeb. | Q9: 0.5 | R9: =+Q9*O9
A10: 60528 Frankfurt | E10: Leistungsdatum:* | G10: =+G7 | L10: zum Gewerbesteuermeßbetrag und zur Feststellung
E11: IBAN: | F11: DE 13 50070024 0 4092862 00 | L11: körperschaftsteuerlicher Bemessungsgrundlagen 2016
E12: BIC: | F12: DEUTDEDBFRA | L12: am 06.09.2017
A17: Rechnung über Honorare
A20: Für die nachfolgend aufgeführten Leistungen erlaube ich mir nach der Steuerberatervergütungs-
A21: verordnung wie folgt abzurechnen:
A23: Leistung | E23: Gegenstands- | F23: Tabelle | G23: Geb.- | H23: Gebühr
A24: §§ | E24: wert | G24: satz
A25: 35 | B25: Jahresabschluß | C25: 2018 | E25: =+(J25+K25)/2 | F25: B | G25: 24 | H25: =G25/10*885 | J25: 367890.87 | K25: 1146065.6
A27: 35 | B27: Steuerbilanz und -GuV | C27: =+C25 | E27: =+(J27+K27)/2 | F27: B | G27: 7.5 | H27: =G27/10*885 | J27: 352410.87 | K27: =+K25
A29: 24 | B29: Umsatzsteuerjahreserklärung | C29: =+C27 | E29: =+(713434+334529)/10 | F29: A | G29: 2 | H29: =G29/10*1422
A31: 24 | B31: Gewerbesteuererklärung nach dem Gewerbe- | E31: 8000 | F31: A | G31: 2 | H31: =G31/10*443
B32: ertrag für | C32: =+C25
A34: 24 | B34: Körperschaftsteuererklärung für | C34: =+C32 | E34: 16000 | F34: A | G34: 2 | H34: =G34/10*594
A36: 24 | B36: Erklärung zur gesonderten Ermittlung von Be- | E36: 8000 | F36: A | G36: 1 | H36: =G36/10*443
B37: steuerungsgrundlagen nach §§ 27 ff. KStG
B38: auf den 31.12. | C38: =+C34
A41: 16 | B41: Auslagenersatz für Post- und | E41: =SUM(H25:H37)*0.15 | G41: 0 | H41: 20
B42: Telekommunikation
A43: *sofern nicht separat anders angegeben | E43: Zwischensumme | H43: =SUM(H25:H42) | I43: =+H43-'JA 2017'!H45
E44: Umsatzsteuer 19% | H44: =+H43*0.19
E45: Rechnungsbetrag | H45: =SUM(H43:H44)
A52: Steuernummer: 012 801 35159

Sheet Löhne IV-2019
A5: Hartmut Ahting, Steuerberater, Heerstrasse 50, 60488 Frankfurt
A7: Franz Pfaff Innenausbau GmbH | E7: Rg-Datum: | G7: 43924
A8: Donnersbergstraße 25 | E8: Kunden-Nr.: | G8: 10113 | L8: - Einrichten von Lohnkonten | M8: 43700 | O8: 9 | Q8: 1 | R8: =+Q8*O8
E9: Rg-Nr.: | G9: 10113-2020-001 | L9: (Nikola Vincetic) | M9: 3
A10: 60528 Frankfurt | E10: IBAN: | F10: DE 13 50070024 0 4092862 00
E11: BIC: | F11: DEUTDEDBFRA
L12: - Einrichten von Lohnkonten | M12: 43792 | O12: 9 | Q12: 1 | R12: =+Q12*O12
L13: (Samual Perikic)
A14: Rechnung über Honorare
A16: Für die nachfolgend aufgeführten Leistungen erlaube ich mir nach der Steuerberatervergütungs-
A17: verordnung wie folgt abzurechnen:
A19: Leistung | E19: Gegenstands- | F19: Tabelle | G19: Arbeit- | H19: Gebühr
A20: §§ | C20: am/in: | E20: wert | G20: nehmer
A21: 34 | B21: Löhne/Gehälter 10/2019
B22: - Lohnabrechnungen inkl.
B23: Sozialvers.-meldungen | C23: 43762 | E23: 15 | G23: 14 | H23: =+G23*E23
A25: 34 | B25: Löhne/Gehälter 11/2019
B26: - Lohnabrechnungen inkl.
B27: Sozialvers.-meldungen | C27: 43792 | E27: 15 | G27: 14 | H27: =+G27*E27
A29: 34 | B29: Löhne/Gehälter 12/2019
B30: - Lohnabrechnungen inkl.
B31: Sozialvers.-meldungen | C31: 43818 | E31: 15 | G31: 13 | H31: =+G31*E31
A33: 34 | B33: Hilfeleistung bei sonstigen Tätigkeiten im Zusammen- | E33: 80 | F33: Zeitgeb. | G33: 1 | H33: =+G33*E33
B34: hang mit dem Lohnsteuerabzug/der Lohnbuchführung
B35: - LFZ-Anträge Münster, M.Perikic, | C35: =+C27
B36: V. Perikic, Orsolic, Bilic,
B37: =+B35 | C37: =+C31
B38: V. Perikic, Orsolic, Bilic,
A40: 16 | B40: Auslagenersatz für Post- und
B41: Telekommunikation | C41: IV/2019 | E41: =SUM(H21:H32)*0.2 | H41: =(G23+G27+G31)*1.3
E43: Gesamt | H43: =SUM(H21:H42)
E44: USt 19% | H44: =+H43*0.19
E45: Rechnungsendbetrag | H45: =SUM(H43:H44)
A47: Bitte überweisen Sie den Betrag ohne Abzüge innerhalb von 14 Tagen auf das angegebene Konto.
A54: Steuernummer: 012 801 35159

Sheet Fibu IV-2019
A5: Hartmut Ahting, Steuerberater, Heerstrasse 50, 60488 Frankfurt
A7: Franz Pfaff Innenausbau GmbH | E7: Rg-Datum: | G7: 43924
A8: Donnersbergstraße 25 | E8: Kunden-Nr.: | G8: 10113
E9: Rg-Nr.: | G9: 10113-2020-002
A10: 60528 Frankfurt | E10: IBAN: | F10: DE 13 50070024 0 4092862 00
E11: BIC: | F11: DEUTDEDBFRA
A16: Rechnung über Honorare
A19: Für die nachfolgend aufgeführten Leistungen erlaube ich mir nach der Steuerberatervergütungs-
A20: verordnung wie folgt abzurechnen:
A22: Leistung | E22: Gegenstands- | F22: Tabelle | G22: Geb.- | H22: Gebühr
A23: §§ | C23: am | E23: wert | G23: satz
A24: 33 | B24: Buchführung einschl. Kontieren der Belege | E24: 1457826 | F24: C | G24: 1.75 | H24: =G24/10*1115
B25: für 10/2019 am | C25: 43804
A27: 33 | B27: Buchführung einschl. Kontieren der Belege | E27: =+E24 | F27: C | G27: =+G24 | H27: =G27/10*1115
B28: für 11/2019 am | C28: 43838
A30: 33 | B30: Buchführung einschl. Kontieren der Belege | E30: =+E27 | F30: C | G30: 2 | H30: =G30/10*1115
B31: für 12/2019 am | C31: 43868
E34: Gesamt | H34: =SUM(H24:H33)
E35: USt 19% | H35: =+H34*0.19
E36: Rechnungsendbetrag | H36: =SUM(H34:H35)
A38: Bitte überweisen Sie den Betrag ohne Abzüge innerhalb von 14 Tagen auf das angegebene Konto.
A51: Steuernummer: 012 801 35159

Sheet Löhne I-2020
A5: Hartmut Ahting, Steuerberater, Heerstrasse 50, 60488 Frankfurt
A7: Franz Pfaff Innenausbau GmbH | E7: Rg-Datum: | G7: 43924
A8: Donnersbergstraße 25 | E8: Kunden-Nr.: | G8: 10113
E9: Rg-Nr.: | G9: 10113-2020-003
A10: 60528 Frankfurt | E10: IBAN: | F10: DE 13 50070024 0 4092862 00
E11: BIC: | F11: DEUTDEDBFRA
A15: Rechnung über Honorare
A17: Für die nachfolgend aufgeführten Leistungen erlaube ich mir nach der Steuerberatervergütungs-
A18: verordnung wie folgt abzurechnen:
A20: Leistung | E20: Gegenstands- | F20: Tabelle | G20: Arbeit- | H20: Gebühr
A21: §§ | C21: am/in: | E21: wert | G21: nehmer
A22: 34 | B22: Löhne/Gehälter 01/2020
B23: - Lohnabrechnungen inkl.
B24: Sozialvers.-meldungen | C24: 43857 | E24: 15 | G24: 13 | H24: =+G24*E24
A26: 34 | B26: Löhne/Gehälter 02/2020
B27: - Lohnabrechnungen inkl.
B28: Sozialvers.-meldungen | C28: 43882 | E28: 15 | G28: 12 | H28: =+G28*E28
A30: 34 | B30: Löhne/Gehälter 03/2020
B31: - Lohnabrechnungen inkl.
B32: Sozialvers.-meldungen | C32: 43914 | E32: 15 | G32: 12 | H32: =+G32*E32
A34: 34 | B34: Hilfeleistung bei sonstigen Tätigkeiten im Zusammen- | E34: 80 | F34: Zeitgeb. | G34: 0.5 | H34: =+G34*E34
B35: hang mit dem Lohnsteuerabzug/der Lohnbuchführung
B36: - LFZ-Anträge Pejacovic, M. Perikic | C36: =+C24
A39: 16 | B39: Auslagenersatz für Post- und
B40: Telekommunikation | C40: I/2020 | E40: =SUM(H22:H35)*0.2 | H40: =SUM(G24:G32)*1.3-1.3
E42: Gesamt | H42: =SUM(H22:H41)
E43: USt 19% | H43: =+H42*0.19
E44: Rechnungsendbetrag | H44: =SUM(H42:H43)
A46: Bitte überweisen Sie den Betrag ohne Abzüge innerhalb von 14 Tagen auf das angegebene Konto.
A54: Steuernummer: 012 801 35159

Sheet Fibu I-2020
A5: Hartmut Ahting, Steuerberater, Heerstrasse 50, 60488 Frankfurt
A7: Franz Pfaff Innenausbau GmbH | E7: Rg-Datum: | G7: 44015
A8: Donnersbergstraße 25 | E8: Kunden-Nr.: | G8: 10113
E9: Rg-Nr.: | G9: 10113-2020-004
A10: 60528 Frankfurt | E10: IBAN: | F10: DE 13 50070024 0 4092862 00
E11: BIC: | F11: DEUTDEDBFRA
A16: Rechnung über Honorare
A19: Für die nachfolgend aufgeführten Leistungen erlaube ich mir nach der Steuerberatervergütungs-
A20: verordnung wie folgt abzurechnen:
A22: Leistung | E22: Gegenstands- | F22: Tabelle | G22: Geb.- | H22: Gebühr
A23: §§ | C23: am | E23: wert | G23: satz
A24: 33 | B24: Buchführung einschl. Kontieren der Belege | E24: 1036500 | F24: C | G24: 3 | H24: =G24/10*761
B25: für 01/2020 am | C25: 43929
A27: 33 | B27: Buchführung einschl. Kontieren der Belege | E27: =+E24 | F27: C | G27: 3 | H27: =G27/10*761
B28: für 02/2020 am | C28: 43936
A30: 33 | B30: Buchführung einschl. Kontieren der Belege | E30: =+E27 | F30: C | G30: 3 | H30: =G30/10*761
B31: für 03/2020 am | C31: =+C28
E34: Gesamt | H34: =SUM(H24:H33)
E35: USt 19% | H35: =+H34*0.19
E36: Rechnungsendbetrag | H36: =SUM(H34:H35)
A38: Bitte überweisen Sie den Betrag ohne Abzüge innerhalb von 14 Tagen auf das angegebene Konto.
A51: Steuernummer: 012 801 35159

Sheet Löhne II-2020
L2: - Einrichten von Lohnkonten | M2: 43945 | O2: 9 | Q2: 1 | R2: =+Q2*O2
L3: (Zlatko Stjepanovic)
A5: Hartmut Ahting, Steuerberater, Heerstrasse 50, 60488 Frankfurt
A7: Franz Pfaff Innenausbau GmbH | E7: Rg-Datum: | G7: 44015
A8: Donnersbergstraße 25 | E8: Kunden-Nr.: | G8: 10113
E9: Rg-Nr.: | G9: 10113-2020-005
A10: 60528 Frankfurt | E10: IBAN: | F10: DE 13 50070024 0 4092862 00
E11: BIC: | F11: DEUTDEDBFRA
A15: Rechnung über Honorare
A18: Für die nachfolgend aufgeführten Leistungen erlaube ich mir nach der Steuerberatervergütungs-
A19: verordnung wie folgt abzurechnen:
A21: Leistung | E21: Gegenstands- | F21: Tabelle | G21: Arbeit- | H21: Gebühr | L21: - LFZ-Anträge Chmielowski
A22: §§ | C22: am/in: | E22: wert | G22: nehmer | L22: - LFZ-Anträge Mita, Chmielowski
A23: 34 | B23: Löhne/Gehälter 04/2020
B24: - Lohnabrechnungen inkl.
B25: Sozialvers.-meldungen | C25: 43948 | E25: 15 | G25: 12 | H25: =+G25*E25
A27: 34 | B27: Löhne/Gehälter 05/2020
B28: - Lohnabrechnungen inkl.
B29: Sozialvers.-meldungen | C29: 43971 | E29: 15 | G29: 12 | H29: =+G29*E29
A31: 34 | B31: Löhne/Gehälter 06/2020
B32: - Lohnabrechnungen inkl.
B33: Sozialvers.-meldungen | C33: 44005 | E33: 15 | G33: =+G29 | H33: =+G33*E33
A35: 34 | B35: Hilfeleistung bei sonstigen Tätigkeiten im Zusammen- | E35: 80 | F35: Zeitgeb. | G35: 0.5 | H35: =+G35*E35
B36: hang mit dem Lohnsteuerabzug/der Lohnbuchführung
B37: - LFZ-Anträge Münster, V.Perikic, Pejakovic
B38: in | C38: II/2020
A40: 16 | B40: Auslagenersatz für Post- und
B41: Telekommunikation | C41: II/2020 | E41: =SUM(H23:H34)*0.2 | H41: =SUM(G25:G33)*1.3
E43: Gesamt | H43: =SUM(H23:H42)
E44: USt 19% | H44: =+H43*0.19
E45: Rechnungsendbetrag | H45: =SUM(H43:H44)
A47: Bitte überweisen Sie den Betrag ohne Abzüge innerhalb von 14 Tagen auf das angegebene Konto.
A55: Steuernummer: 012 801 35159

Sheet Fibu II-2020
A5: Hartmut Ahting, Steuerberater, Heerstrasse 50, 60488 Frankfurt
A7: Franz Pfaff Innenausbau GmbH | E7: Rg-Datum: | G7: 44449
A8: Donnersbergstraße 25 | E8: Kunden-Nr.: | G8: 10113
E9: Rg-Nr.: | G9: 10113-2020-006
A10: 60528 Frankfurt | E10: IBAN: | F10: DE 13 50070024 0 4092862 00
E11: BIC: | F11: DEUTDEDBFRA
A16: Rechnung über Honorare
A19: Für die nachfolgend aufgeführten Leistungen erlaube ich mir nach der Steuerberatervergütungs-
A20: verordnung wie folgt abzurechnen:
A22: Leistung | E22: Gegenstands- | F22: Tabelle | G22: Geb.- | H22: Gebühr
A23: §§ | C23: am | E23: wert | G23: satz
A24: 33 | B24: Buchführung einschl. Kontieren der Belege | E24: 1036000 | F24: C | G24: 3 | H24: =G24/10*761
B25: für 04/2020 am | C25: 44021
A27: 33 | B27: Buchführung einschl. Kontieren der Belege | E27: =+E24 | F27: C | G27: =+G24 | H27: =G27/10*761
B28: für 05/2020 am | C28: 44021
A30: 33 | B30: Buchführung einschl. Kontieren der Belege | E30: =+E27 | F30: C | G30: =+G27 | H30: =G30/10*761
B31: für 06/2020 am | C31: 44042
B33: Rat/Auskunft | C33: 44050 | E33: 6000 | F33: A | G33: 3 | H33: =G33/10*355
B34: Zusammenstellung von Daten für die Bauhaupterhebung
B35: des stat. Landesamtes 2020
E37: Gesamt | H37: =SUM(H24:H36)
E38: USt 16% | H38: =+H37*0.16
E39: Rechnungsendbetrag | H39: =SUM(H37:H38)
A41: Bitte überweisen Sie den Betrag ohne Abzüge innerhalb von 14 Tagen auf das angegebene Konto.
A51: Steuernummer: 012 801 35159

Sheet Löhne III-2020
A5: Hartmut Ahting, Steuerberater, Heerstrasse 50, 60488 Frankfurt
A7: Franz Pfaff Innenausbau GmbH | E7: Rg-Datum: | G7: 44169
A8: Donnersbergstraße 25 | E8: Kunden-Nr.: | G8: 10113
E9: Rg-Nr.: | G9: 10113-2020-007
A10: 60528 Frankfurt | E10: IBAN: | F10: DE 13 50070024 0 4092862 00
E11: BIC: | F11: DEUTDEDBFRA
A15: Rechnung über Honorare
A17: Für die nachfolgend aufgeführten Leistungen erlaube ich mir nach der Steuerberatervergütungs-
A18: verordnung wie folgt abzurechnen:
A20: Leistung | E20: Gegenstands- | F20: Tabelle | G20: Arbeit- | H20: Gebühr
A21: §§ | C21: am/in: | E21: wert | G21: nehmer
A22: 34 | B22: Löhne/Gehälter 07/2020
B23: - Lohnabrechnungen inkl.
B24: Sozialvers.-meldungen | C24: 44039 | E24: 15 | G24: 12 | H24: =+G24*E24
A26: 34 | B26: Löhne/Gehälter 08/2020
B27: - Lohnabrechnungen inkl.
B28: Sozialvers.-meldungen | C28: 44067 | E28: 15 | G28: 12 | H28: =+G28*E28
A30: 34 | B30: Löhne/Gehälter 09/2020
B31: - Einrichten von Lohnkonten | C31: 08/2020 | E31: 9 | G31: 1 | H31: =+G31*E31
B32: (S.Perikic)
B33: - Lohnabrechnungen inkl.
B34: Sozialvers.-meldungen | C34: 43366 | E34: 15 | G34: 12 | H34: =+G34*E34
A36: 34 | B36: Hilfeleistung bei sonstigen Tätigkeiten im Zusammen- | E36: 80 | F36: Zeitgeb. | G36: 1.5 | H36: =+G36*E36
B37: hang mit dem Lohnsteuerabzug/der Lohnbuchführung
B38: - Klärung von Rückfragen desArbeitsamtes zu
B39: Winterbauumlage | C39: =+C31
A41: 16 | B41: Auslagenersatz für Post- und
B42: Telekommunikation | C42: III/2020 | E42: =SUM(H22:H35)*0.2 | H42: =(G24+G28+G34)*1.3
E44: Gesamt | H44: =SUM(H22:H43)
E45: USt 16% | H45: =+H44*0.16
E46: Rechnungsendbetrag | H46: =SUM(H44:H45)
A48: Bitte überweisen Sie den Betrag ohne Abzüge innerhalb von 14 Tagen auf das angegebene Konto.
A54: Steuernummer: 012 801 35159

Sheet Fibu III-2020
A5: Hartmut Ahting, Steuerberater, Heerstrasse 50, 60488 Frankfurt
A7: Franz Pfaff Innenausbau GmbH | E7: Rg-Datum: | G7: 44169
A8: Donnersbergstraße 25 | E8: Kunden-Nr.: | G8: 10113
E9: Rg-Nr.: | G9: 10113-2020-008
A10: 60528 Frankfurt | E10: IBAN: | F10: DE 13 50070024 0 4092862 00
E11: BIC: | F11: DEUTDEDBFRA
A16: Rechnung über Honorare
A19: Für die nachfolgend aufgeführten Leistungen erlaube ich mir nach der Steuerberatervergütungs-
A20: verordnung wie folgt abzurechnen:
A22: Leistung | E22: Gegenstands- | F22: Tabelle | G22: Geb.- | H22: Gebühr
A23: §§ | C23: am | E23: wert | G23: satz
A24: 33 | B24: Buchführung einschl. Kontieren der Belege | E24: =ROUND((1009597/10*12)/100,)*100 | F24: C | G24: 2.5 | H24: =G24/10*993
B25: für 07/2020 am | C25: 44109
A27: 33 | B27: Buchführung einschl. Kontieren der Belege | E27: =+E24 | F27: C | G27: 2.5 | H27: =G27/10*993
B28: für 08/2020 am | C28: =+C25
A30: 33 | B30: Buchführung einschl. Kontieren der Belege | E30: =+E27 | F30: C | G30: 2.5 | H30: =G30/10*993
B31: für 09/2020 am | C31: 44141
E34: Gesamt | H34: =SUM(H24:H33)
E35: USt 16% | H35: =+H34*0.16
E36: Rechnungsendbetrag | H36: =SUM(H34:H35)
A38: Bitte überweisen Sie den Betrag ohne Abzüge innerhalb von 14 Tagen auf das angegebene Konto.
A51: Steuernummer: 012 801 35159

Sheet Löhne IV-2020
M3: - Einrichten von Lohnkonten | N3: 08/2020 | P3: 9 | R3: 1 | S3: =+R3*P3
M4: (S.Perikic)
A5: Hartmut Ahting, Steuerberater, Heerstrasse 50, 60488 Frankfurt
A7: Franz Pfaff Innenausbau GmbH | E7: Rg-Datum: | G7: 44277
A8: Donnersbergstraße 25 | E8: Kunden-Nr.: | G8: 10113
E9: Rg-Nr.: | G9: 10113-2021-001
A10: 60528 Frankfurt | E10: IBAN: | F10: DE 13 50070024 0 4092862 00
E11: BIC: | F11: DEUTDEDBFRA
A15: Rechnung über Honorare
A17: Für die nachfolgend aufgeführten Leistungen erlaube ich mir nach der Steuerberatervergütungs-
A18: verordnung wie folgt abzurechnen:
A20: Leistung | E20: Gegenstands- | F20: Tabelle | G20: Arbeit- | H20: Gebühr
A21: §§ | C21: am/in: | E21: wert | G21: nehmer
A22: 34 | B22: Löhne/Gehälter 10/2020
B23: - Lohnabrechnungen inkl.
B24: Sozialvers.-meldungen | C24: 44127 | E24: 15 | G24: 13 | H24: =+G24*E24
A26: 34 | B26: Löhne/Gehälter 11/2020
B27: - Lohnabrechnungen inkl.
B28: Sozialvers.-meldungen | C28: 44158 | E28: 15 | G28: 13 | H28: =+G28*E28
A30: 34 | B30: Löhne/Gehälter 12/2020
B31: - Lohnabrechnungen inkl.
B32: Sozialvers.-meldungen | C32: 44182 | E32: 15 | G32: 13 | H32: =+G32*E32
A34: 34 | B34: Hilfeleistung bei sonstigen Tätigkeiten im Zusammen- | E34: 80 | F34: Zeitgeb. | G34: 2 | H34: =+G34*E34
B35: hang mit dem Lohnsteuerabzug/der Lohnbuchführung
B36: - LFZ-Anträge Chmielowski (2x), M.Perikic (3x), Perikic,
B37: S. (2x), Münster, Stjepanovic | C37: IV/2020
A39: 16 | B39: Auslagenersatz für Post- und
B40: Telekommunikation | C40: IV/2020 | E40: =SUM(H22:H33)*0.2 | H40: =(G24+G28+G32)*1.3
E42: Gesamt | H42: =SUM(H22:H41)
E43: USt 16% | H43: =+H42*0.16
E44: Rechnungsendbetrag | H44: =SUM(H42:H43)
A46: Bitte überweisen Sie den Betrag ohne Abzüge innerhalb von 14 Tagen auf das angegebene Konto.
A54: Steuernummer: 012 801 35159

Sheet Fibu IV-2020
A5: Hartmut Ahting, Steuerberater, Heerstrasse 50, 60488 Frankfurt
A7: Franz Pfaff Innenausbau GmbH | E7: Rg-Datum: | G7: 44277
A8: Donnersbergstraße 25 | E8: Kunden-Nr.: | G8: 10113
E9: Rg-Nr.: | G9: 10113-2021-002
A10: 60528 Frankfurt | E10: IBAN: | F10: DE 13 50070024 0 4092862 00
E11: BIC: | F11: DEUTDEDBFRA
A16: Rechnung über Honorare
A19: Für die nachfolgend aufgeführten Leistungen erlaube ich mir nach der Steuerberatervergütungs-
A20: verordnung wie folgt abzurechnen:
A22: Leistung | E22: Gegenstands- | F22: Tabelle | G22: Geb.- | H22: Gebühr
A23: §§ | C23: am | E23: wert | G23: satz
A24: 33 | B24: Buchführung einschl. Kontieren der Belege | E24: =ROUND((1009597/10*12)/100,)*100 | F24: C | G24: 2.5 | H24: =G24/10*993
B25: für 10/2020 am | C25: 44215
A27: 33 | B27: Buchführung einschl. Kontieren der Belege | E27: =+E24 | F27: C | G27: =+G24 | H27: =G27/10*993
B28: für 11/2020 am | C28: =+C25
A30: 33 | B30: Buchführung einschl. Kontieren der Belege | E30: =+E27 | F30: C | G30: 3 | H30: =G30/10*993
B31: für 12/2020 am | C31: 44231
E34: Gesamt | H34: =SUM(H24:H33)
E35: USt 19% | H35: =+H34*0.19
E36: Rechnungsendbetrag | H36: =SUM(H34:H35)
A38: Bitte überweisen Sie den Betrag ohne Abzüge innerhalb von 14 Tagen auf das angegebene Konto.
A51: Steuernummer: 012 801 35159

Sheet Löhne I-2021
A5: Hartmut Ahting, Steuerberater, Heerstrasse 50, 60488 Frankfurt
A7: Franz Pfaff Innenausbau GmbH | E7: Rg-Datum: | G7: 44323
A8: Donnersbergstraße 25 | E8: Kunden-Nr.: | G8: 10113
E9: Rg-Nr.: | G9: 10113-2021-003
A10: 60528 Frankfurt | E10: IBAN: | F10: DE 13 50070024 0 4092862 00
E11: BIC: | F11: DEUTDEDBFRA
A15: Rechnung über Honorare
A17: Für die nachfolgend aufgeführten Leistungen erlaube ich mir nach der Steuerberatervergütungs-
A18: verordnung wie folgt abzurechnen:
A20: Leistung | E20: Gegenstands- | F20: Tabelle | G20: Arbeit- | H20: Gebühr
A21: §§ | C21: am/in: | E21: wert | G21: nehmer
A22: 34 | B22: Löhne/Gehälter 01/2021
B23: - Lohnabrechnungen inkl.
B24: Sozialvers.-meldungen | C24: 44222 | E24: 15 | G24: 12 | H24: =+G24*E24
A26: 34 | B26: Löhne/Gehälter 02/2021
B27: - Lohnabrechnungen inkl.
B28: Sozialvers.-meldungen | C28: 44246 | E28: 15 | G28: 12 | H28: =+G28*E28
A30: 34 | B30: Löhne/Gehälter 03/2021
B31: - Einrichten von Lohnkonten / | C31: 03/2021 | E31: 15 | G31: 1 | H31: =+G31*E31
B32: Sofortmeldung (M. Jurkovic)
B33: - Lohnabrechnungen inkl.
B34: Sozialvers.-meldungen | C34: 44279 | E34: 15 | G34: 13 | H34: =+G34*E34
A36: 34 | B36: Hilfeleistung bei sonstigen Tätigkeiten im Zusammen- | E36: 80 | F36: Zeitgeb. | G36: 1 | H36: =+G36*E36
B37: hang mit dem Lohnsteuerabzug/der Lohnbuchführung
B38: - LFZ-Anträge Chmielowski (2x), M. Perikic, S. Perikic (2x),
B39: Münster, Milicevic | C39: I/2021
A41: 16 | B41: Auslagenersatz für Post- und
B42: Telekommunikation | C42: I/2021 | E42: =SUM(H22:H37)*0.2 | H42: =SUM(G24:G34)*1.3-1.3
E44: Gesamt | H44: =SUM(H22:H43)
E45: USt 19% | H45: =+H44*0.19
E46: Rechnungsendbetrag | H46: =SUM(H44:H45)
A48: Bitte überweisen Sie den Betrag ohne Abzüge innerhalb von 14 Tagen auf das angegebene Konto.
A55: Steuernummer: 012 801 35159

Sheet Fibu I-2021
A5: Hartmut Ahting, Steuerberater, Heerstrasse 50, 60488 Frankfurt
A7: Franz Pfaff Innenausbau GmbH | E7: Rg-Datum: | G7: 44333
A8: Donnersbergstraße 25 | E8: Kunden-Nr.: | G8: 10113
E9: Rg-Nr.: | G9: 10113-2021-004
A10: 60528 Frankfurt | E10: IBAN: | F10: DE 13 50070024 0 4092862 00
E11: BIC: | F11: DEUTDEDBFRA
A16: Rechnung über Honorare
A19: Für die nachfolgend aufgeführten Leistungen erlaube ich mir nach der Steuerberatervergütungs-
A20: verordnung wie folgt abzurechnen:
A22: Leistung | E22: Gegenstands- | F22: Tabelle | G22: Geb.- | H22: Gebühr
A23: §§ | C23: am | E23: wert | G23: satz
A24: 33 | B24: Buchführung einschl. Kontieren der Belege | E24: =ROUND((1009597/10*12)/100,)*100 | F24: C | G24: 3.25 | H24: =G24/10*993
B25: für 01/2021 am | C25: 44264
A27: 33 | B27: Buchführung einschl. Kontieren der Belege | E27: =+E24 | F27: C | G27: =+G24 | H27: =G27/10*993
B28: für 02/2021 am | C28: 44286
A30: 33 | B30: Buchführung einschl. Kontieren der Belege | E30: =+E27 | F30: C | G30: =+G24 | H30: =G30/10*993
B31: für 03/2021 am | C31: 44327
E34: Gesamt | H34: =SUM(H24:H33)
E35: USt 19% | H35: =+H34*0.19
E36: Rechnungsendbetrag | H36: =SUM(H34:H35)
A38: Bitte überweisen Sie den Betrag ohne Abzüge innerhalb von 14 Tagen auf das angegebene Konto.
A51: Steuernummer: 012 801 35159

Sheet Löhne II-2021
A5: Hartmut Ahting, Steuerberater, Heerstrasse 50, 60488 Frankfurt
A7: Franz Pfaff Innenausbau GmbH | E7: Rg-Datum: | G7: 44449
A8: Donnersbergstraße 25 | E8: Kunden-Nr.: | G8: 10113
E9: Rg-Nr.: | G9: 10113-2021-005
A10: 60528 Frankfurt | E10: Leistungsdatum: | G10: siehe Einzelposition
E11: IBAN: | F11: DE 13 50070024 0 4092862 00
E12: BIC: | F12: DEUTDEDBFRA
A15: Rechnung über Honorare
A17: Für die nachfolgend aufgeführten Leistungen erlaube ich mir nach der Steuerberatervergütungs-
A18: verordnung wie folgt abzurechnen:
A20: Leistung | E20: Gegenstands- | F20: Tabelle | G20: Arbeit- | H20: Gebühr
A21: §§ | C21: am/in: | E21: wert | G21: nehmer
A22: 34 | B22: Löhne/Gehälter 04/2021
B23: - Einrichten von Lohnkonten / | C23: 04/2021 | E23: 15 | G23: 1 | H23: =+G23*E23
B24: - Lohnabrechnungen inkl.
B25: Sozialvers.-meldungen | C25: 44311 | E25: 15 | G25: 14 | H25: =+G25*E25
A27: 34 | B27: Löhne/Gehälter 05/2021
B28: - Lohnabrechnungen inkl.
B29: Sozialvers.-meldungen | C29: 44342 | E29: 15 | G29: 14 | H29: =+G29*E29
A31: 34 | B31: Löhne/Gehälter 06/2021
B32: - Lohnabrechnungen inkl.
B33: Sozialvers.-meldungen | C33: 44371 | E33: 15 | G33: 13 | H33: =+G33*E33
A35: 34 | B35: Hilfeleistung bei sonstigen Tätigkeiten im Zusammen- | E35: 80 | F35: Zeitgeb. | G35: 0.5 | H35: =+G35*E35
B36: hang mit dem Lohnsteuerabzug/der Lohnbuchführung
B37: - LFZ-Anträge M. Perikic, V.Perikic, Boycjinov
B38: in | C38: II/2021
A40: 16 | B40: Auslagenersatz für Post- und
B41: Telekommunikation | C41: II/2021 | E41: =SUM(H22:H34)*0.2 | H41: 60
E43: Gesamt | H43: =SUM(H22:H42)
E44: USt 19% | H44: =+H43*0.19
E45: Rechnungsendbetrag | H45: =SUM(H43:H44)
A47: Bitte überweisen Sie den Betrag ohne Abzüge innerhalb von 14 Tagen auf das angegebene Konto.
A55: Steuernummer: 012 801 35159

Sheet Fibu II-2021
A5: Hartmut Ahting, Steuerberater, Heerstrasse 50, 60488 Frankfurt
A7: Franz Pfaff Innenausbau GmbH | E7: Rg-Datum: | G7: 44449
A8: Donnersbergstraße 25 | E8: Kunden-Nr.: | G8: 10113
E9: Rg-Nr.: | G9: 10113-2021-006
A10: 60528 Frankfurt | E10: IBAN: | F10: DE 13 50070024 0 4092862 00
E11: BIC: | F11: DEUTDEDBFRA
A16: Rechnung über Honorare
A19: Für die nachfolgend aufgeführten Leistungen erlaube ich mir nach der Steuerberatervergütungs-
A20: verordnung wie folgt abzurechnen:
A22: Leistung | E22: Gegenstands- | F22: Tabelle | G22: Geb.- | H22: Gebühr
A23: §§ | C23: am | E23: wert | G23: satz
A24: 33 | B24: Buchführung einschl. Kontieren der Belege | E24: 1036000 | F24: C | G24: 6 | H24: =G24/10*857
B25: für 04/2021 am | C25: 44357
A27: 33 | B27: Buchführung einschl. Kontieren der Belege | E27: =+E24 | F27: C | G27: =+G24 | H27: =G27/10*857
B28: für 05/2021 am | C28: 44384
A30: 33 | B30: Buchführung einschl. Kontieren der Belege | E30: =+E27 | F30: C | G30: =+G27 | H30: =G30/10*857
B31: für 06/2021 am | C31: 44414
B33: Rat/Auskunft | C33: 44415 | E33: 6000 | F33: A | G33: 3 | H33: =G33/10*355
B34: Zusammenstellung von Daten für die Bauhaupterhebung
B35: des stat. Landesamtes 2021
E37: Gesamt | H37: =SUM(H24:H36)
E38: USt 19% | H38: =+H37*0.19
E39: Rechnungsendbetrag | H39: =SUM(H37:H38)
A41: Bitte überweisen Sie den Betrag ohne Abzüge innerhalb von 14 Tagen auf das angegebene Konto.
A51: Steuernummer: 012 801 35159

Sheet Fibu III-2021
A5: Hartmut Ahting, Steuerberater, Heerstrasse 50, 60488 Frankfurt
A7: Franz Pfaff Innenausbau GmbH | E7: Rg-Datum: | G7: 44552
A8: Donnersbergstraße 25 | E8: Kunden-Nr.: | G8: 10113
E9: Rg-Nr.: | G9: 10113-2021-007
A10: 60528 Frankfurt | E10: IBAN: | F10: DE 13 50070024 0 4092862 00
E11: BIC: | F11: DEUTDEDBFRA
A16: Rechnung über Honorare
A19: Für die nachfolgend aufgeführten Leistungen erlaube ich mir nach der Steuerberatervergütungs-
A20: verordnung wie folgt abzurechnen:
A22: Leistung | E22: Gegenstands- | F22: Tabelle | G22: Geb.- | H22: Gebühr
A23: §§ | C23: am | E23: wert | G23: satz
A24: 33 | B24: Buchführung einschl. Kontieren der Belege | E24: 1300000 | F24: C | G24: 2.5 | H24: =G24/10*1027
B25: für 07/2021 am | C25: 44447
A27: 33 | B27: Buchführung einschl. Kontieren der Belege | E27: =+E24 | F27: C | G27: 3 | H27: =G27/10*1027
B28: für 08/2021 am | C28: 44474
A30: 33 | B30: Buchführung einschl. Kontieren der Belege | E30: =+E27 | F30: C | G30: 3 | H30: =G30/10*1027
B31: für 09/2021 am | C31: 44508
E34: Gesamt | H34: =SUM(H24:H33)
E35: USt 19% | H35: =+H34*0.19
E36: Rechnungsendbetrag | H36: =SUM(H34:H35)
A38: Bitte überweisen Sie den Betrag ohne Abzüge innerhalb von 14 Tagen auf das angegebene Konto.
A51: Steuernummer: 012 801 35159

Sheet Löhne III-2021
A5: Hartmut Ahting, Steuerberater, Heerstrasse 50, 60488 Frankfurt
A7: Franz Pfaff Innenausbau GmbH | E7: Rg-Datum: | G7: 44552
A8: Donnersbergstraße 25 | E8: Kunden-Nr.: | G8: 10113
E9: Rg-Nr.: | G9: 10113-2021-008
A10: 60528 Frankfurt | E10: IBAN: | F10: DE 13 50070024 0 4092862 00
E11: BIC: | F11: DEUTDEDBFRA
A15: Rechnung über Honorare
L16: - Einrichten von Lohnkonten | M16: 08/2021 | O16: 9 | Q16: 1 | R16: =+Q16*O16
A17: Für die nachfolgend aufgeführten Leistungen erlaube ich mir nach der Steuerberatervergütungs- | L17: (S.Perikic)
A18: verordnung wie folgt abzurechnen:
A20: Leistung | E20: Gegenstands- | F20: Tabelle | G20: Arbeit- | H20: Gebühr
A21: §§ | C21: am/in: | E21: wert | G21: nehmer
A22: 34 | B22: Löhne/Gehälter 07/2021
B23: - Lohnabrechnungen inkl.
B24: Sozialvers.-meldungen | C24: 44404 | E24: 15 | G24: 13 | H24: =+G24*E24
A26: 34 | B26: Löhne/Gehälter 08/2021
B27: - Lohnabrechnungen inkl.
B28: Sozialvers.-meldungen | C28: 44420 | E28: 15 | G28: 13 | H28: =+G28*E28
A30: 34 | B30: Löhne/Gehälter 09/2021
B31: - Lohnabrechnungen inkl.
B32: Sozialvers.-meldungen | C32: 43371 | E32: 15 | G32: 13 | H32: =+G32*E32
A34: 34 | B34: Hilfeleistung bei sonstigen Tätigkeiten im Zusammen- | E34: 80 | F34: Zeitgeb. | G34: 0.5 | H34: =+G34*E34
B35: hang mit dem Lohnsteuerabzug/der Lohnbuchführung
B36: - LFZ-Anträge Chmielowski (2x) | C36: III/2021
A41: 16 | B41: Auslagenersatz für Post- und
B42: Telekommunikation | C42: III/2021 | E42: =SUM(H22:H34)*0.2 | H42: =(G24+G28+G32)*1.3
E44: Gesamt | H44: =SUM(H22:H43)
E45: USt 19% | H45: =+H44*19%
E46: Rechnungsendbetrag | H46: =SUM(H44:H45)
