Workbook

Sheet StBVV
A1: StBVV — Gebührentabellen A, B und C (Anlage 1–3)
A2: Gültig ab 01.07.2025 · 5. Verordnung zur Änderung der StBVV v. 31.03.2025 (BGBl. 2025 I Nr. 105)
A3: Gegenstandswert ab € | B3: A | C3: B | D3: C
A4: (Untergrenze des Tiers für SVERWEIS) | B4: Beratungstabelle | C4: Abschlusstabelle | D4: Buchführung (monatl.)
A5: 1 | B5: 31 | C5: 49 | D5: 72
A6: 301 | B6: 56 | C6: 49 | D6: 72
A7: 601 | B7: 81 | C7: 49 | D7: 72
A8: 901 | B8: 106 | C8: 49 | D8: 72
A9: 1201 | B9: 130 | C9: 49 | D9: 72
A10: 1501 | B10: 166 | C10: 49 | D10: 72
A11: 2001 | B11: 200 | C11: 49 | D11: 72
A12: 2501 | B12: 235 | C12: 49 | D12: 72
A13: 3001 | B13: 270 | C13: 57 | D13: 72
A14: 3501 | B14: 305 | C14: 68 | D14: 72
A15: 4001 | B15: 340 | C15: 76 | D15: 72
A16: 4501 | B16: 375 | C16: 86 | D16: 72
... A70: 550001 | B70: 3404 | C70: 871 | D70: 584
A71: 600001 | C71: 871 | D71: 620
A72: 625001 | C72: 968 | D72: 620
A73: 650001 | C73: 968 | D73: 656
A74: 700001 | C74: 968 | D74: 692
A75: 750001 | C75: 1050 | D75: 728
A76: 800001 | C76: 1050 | D76: 764
A77: 850001 | C77: 1050 | D77: 800
A78: 875001 | C78: 1126 | D78: 800
A79: 900001 | C79: 1126 | D79: 836
A80: 950001 | C80: 1126 | D80: 872
A81: 1000001 | C81: 1194 | D81: 908
A82: 1050001 | C82: 1194 | D82: 944
... A100: 1950001 | C100: 1542 | D100: 1592
A101: 2000001 | D101: 1628
A102: 2050001 | D102: 1664
A103: 2100001 | D103: 1700
A104: 2150001 | D104: 1736
A105: 2200001 | D105: 1772
A106: 2250001 | D106: 1808
A107: 2300001 | D107: 1844
A108: 2350001 | D108: 1880
A109: 2400001 | D109: 1916
A110: 2450001 | D110: 1952
...

Sheet Löhne
A1: An:
A2: Franz Pfaff Innenausbau GmbH
A3: Donnersbergstraße 25
A4: 60528 Frankfurt
A6: Rechnungs-Nr: | B6: 10113-2025-004
A7: Kunden-Nr: | B7: 10113
A8: Rechnungsdatum: | B8: 45853
C10: Rechnung über Honorare
A11: Für die nachfolgend aufgeführten Leistungen erlaube ich mir nach der Steuerberatervergütungsverordnung wie folgt abzurechnen:
A13: Pos. | B13: Datum | C13: §§ / Leistung | D13: Arbeitnehmer | E13: Einheit | F13: Wert | G13: Gebühr | H13: Tabelle (A/B/C)
A14: 1 | B14: 45658 | C14: §34 / Löhne/Gehälter 01/2025 - Einrichten v. Lohnkonten (Vasile) | D14: 1 | E14: Stk. | F14: 9 | G14: =+D14*F14 -> 9
A15: 2 | B15: 45681 | C15: §34 /- Lohnabrechnungen inkl. Sozialvers.-meldungen | D15: 15 | E15: Stk. | F15: 15 | G15: =+D15*F15 -> 225
A16: 3 | B16: 45689 | C16: §34 / Löhne/Gehälter 02/2025 - Einrichten v. Lohnkonten (Bajiric) | D16: 2 | E16: Stk. | F16: 9 | G16: =+D16*F16 -> 18
A17: 4 | B17: 45708 | C17: §34 / -Lohnabrechnungen inkl. Sozialvers.-meldungen | D17: 17 | E17: Stk. | F17: 15 | G17: =+D17*F17 -> 255
A18: 5 | B18: 45740 | C18: §34 / Löhne/Gehälter 03/2025 - Lohnabrechnungen inkl. Sozialvers.-meldungen | D18: 17 | E18: Stk. | F18: 15 | G18: =+D18*F18 -> 255
A19: 6 | B19: 45658 | C19: §16 / Auslagenersatz für Post- und Telekommunikation | D19: 0 | E19: Stk. | F19: =SUM(G14:G18)*0.2 -> 152.4 | G19: 60
F20: Summe | G20: =SUM(G14:G19) -> 822
F21: Umsatzsteuer 19% | G21: =+G20*0.19 -> 156.18
F22: Bruttobetrag | G22: =SUM(G20:G21) -> 978.18

Sheet Fibu
A1: An:
A2: Franz Pfaff Innenausbau GmbH
A3: Donnersbergstraße 25
A4: 60528 Frankfurt
A6: Rechnungs-Nr: | B6: 10113-2025-005
A7: Kunden-Nr: | B7: 10113
A8: Rechnungsdatum: | B8: 45853
C10: Rechnung über Honorare
A11: Für die nachfolgend aufgeführten Leistungen erlaube ich mir nach der Steuerberatervergütungsverordnung wie folgt abzurechnen:
A13: Pos. | B13: Datum | C13: §§ / Leistung | D13: Gebühren-satz | E13: Einheit | F13: Wert | G13: Gebühr | H13: Tabelle (A/B/C)
A14: 1 | B14: 45726 | C14: §33 / Buchführung einschl. Kontieren der Belege für 01/2025 - Tabelle C | D14: 4/10 | E14: Stk. | F14: =338453*4 -> 1353812 | G14: =IFERROR(IF(H14="",IFERROR(VALUE(LEFT(D14,FIND("/",D14)-1))/VALUE(MID(D14,FIND("/",D14)+1,100)),D14)*F14,IFERROR(VALUE(LEFT(D14,FIND("/",D14)-1))/VALUE(MID(D14,FIND("/",D14)+1,100)),D14)*VLOOKUP(F14,StBVV!$A:$D,MATCH(H14,StBVV!$B$3:$D$3,0)+1,TRUE)),IFERROR(VALUE(LEFT(D14,FIND("/",D14)-1))/VALUE(MID(D14,FIND("/",D14)+1,100)),D14)*F14) -> 464 | H14: C
A15: 2 | B15: 45755 | C15: §33 / Buchführung einschl. Kontieren der Belege für 02/2025 - Tabelle C | D15: 4,5/10 | E15: Stk. | F15: =+F14 -> 1353812 | G15: =IFERROR(IF(H15="",IFERROR(VALUE(LEFT(D15,FIND("/",D15)-1))/VALUE(MID(D15,FIND("/",D15)+1,100)),D15)*F15,IFERROR(VALUE(LEFT(D15,FIND("/",D15)-1))/VALUE(MID(D15,FIND("/",D15)+1,100)),D15)*VLOOKUP(F15,StBVV!$A:$D,MATCH(H15,StBVV!$B$3:$D$3,0)+1,TRUE)),IFERROR(VALUE(LEFT(D15,FIND("/",D15)-1))/VALUE(MID(D15,FIND("/",D15)+1,100)),D15)*F15) -> 522 | H15: C
A16: 3 | B16: 45782 | C16: §33 / Buchführung einschl. Kontieren der Belege für 03/2025 - Tabelle C | D16: 3/10 | E16: Stk. | F16: =+F15 -> 1353812 | G16: =IFERROR(IF(H16="",IFERROR(VALUE(LEFT(D16,FIND("/",D16)-1))/VALUE(MID(D16,FIND("/",D16)+1,100)),D16)*F16,IFERROR(VALUE(LEFT(D16,FIND("/",D16)-1))/VALUE(MID(D16,FIND("/",D16)+1,100)),D16)*VLOOKUP(F16,StBVV!$A:$D,MATCH(H16,StBVV!$B$3:$D$3,0)+1,TRUE)),IFERROR(VALUE(LEFT(D16,FIND("/",D16)-1))/VALUE(MID(D16,FIND("/",D16)+1,100)),D16)*F16) -> 348 | H16: C
F17: Summe | G17: =SUM(G14:G16) -> 1334
F18: Umsatzsteuer 19% | G18: =+G17*0.19 -> 253.46
F19: Bruttobetrag | G19: =SUM(G17:G18) -> 1587.46

Sheet JA
A1: An:
A2: Klaus Walter
A3: Neuer Weg 72
A4: 60388 Frankfurt
A6: Rechnungs-Nr: | B6: 10117-2024-004
A7: Kunden-Nr: | B7: 10117
A8: Rechnungsdatum: | B8: 45471
C10: Rechnung über Honorare
A11: Für die nachfolgend aufgeführten Leistungen erlaube ich mir nach der Steuerberatervergütungsverordnung wie folgt abzurechnen:
A13: Pos. | B13: Datum | C13: §§ / Leistung | D13: Gebühren-satz | E13: Einheit | F13: Wert | G13: Gebühr | H13: Tabelle (A/B/C)
A14: 1 | B14: 45471 | C14: §25 / Einnahmenüberschußrechnung 2022 - Tabelle B | D14: 25/10 | E14: Stk. | F14: 39808.88 | G14: =IFERROR(IF(H14="",IFERROR(VALUE(LEFT(D14,FIND("/",D14)-1))/VALUE(MID(D14,FIND("/",D14)+1,100)),D14)*F14,IFERROR(VALUE(LEFT(D14,FIND("/",D14)-1))/VALUE(MID(D14,FIND("/",D14)+1,100)),D14)*VLOOKUP(F14,StBVV!$A:$D,MATCH(H14,StBVV!$B$3:$D$3,0)+1,TRUE)),IFERROR(VALUE(LEFT(D14,FIND("/",D14)-1))/VALUE(MID(D14,FIND("/",D14)+1,100)),D14)*F14) -> 657.5 | H14: B
A15: 2 | B15: 45471 | C15: §25 / Vorarbeiten bei der Ermittlung des Überschusses der Betriebseinnahmen über die Betriebsausgaben 2022 (Ermittlung fehlender Unterlagen, Einarbeitung nachgereichter Belege) | D15: 4 | E15: Stk. | F15: 95 | G15: =IFERROR(IF(H15="",D15*F15,D15/10*VLOOKUP(F15,StBVV!$A:$D,MATCH(H15,StBVV!$B$3:$D$3,0)+1,TRUE)),D15*F15) -> 380
A16: 3 | B16: 45471 | C16: §24 / Umsatzsteuerjahreserklärung für 2022 - Tabelle A | D16: 6/10 | E16: Stk. | F16: 8000 | G16: =IFERROR(IF(H16="",IFERROR(VALUE(LEFT(D16,FIND("/",D16)-1))/VALUE(MID(D16,FIND("/",D16)+1,100)),D16)*F16,IFERROR(VALUE(LEFT(D16,FIND("/",D16)-1))/VALUE(MID(D16,FIND("/",D16)+1,100)),D16)*VLOOKUP(F16,StBVV!$A:$D,MATCH(H16,StBVV!$B$3:$D$3,0)+1,TRUE)),IFERROR(VALUE(LEFT(D16,FIND("/",D16)-1))/VALUE(MID(D16,FIND("/",D16)+1,100)),D16)*F16) -> 308.4 | H16: A
A17: 4 | B17: 45471 | C17: §16 / Auslagenersatz für Post- und Telekommunikation | D17: 1 | E17: Stk. | F17: =SUM(G14:G16)*0.2 -> 269.18 | G17: =IFERROR(IF(H17="",D17*F17,D17/10*VLOOKUP(F17,StBVV!$A:$D,MATCH(H17,StBVV!$B$3:$D$3,0)+1,TRUE)),D17*F17) -> 269.18
F19: Summe | G19: =SUM(G14:G17) -> 1615.08
F20: Umsatzsteuer 19% | G20: =+G19*0.19 -> 306.8652
F21: Bruttobetrag | G21: =SUM(G19:G20) -> 1921.9452

Sheet GrSt
A1: An:
A2: Klaus Walter
A3: Neuer Weg 72
A4: 60388 Frankfurt
A6: Rechnungs-Nr: | B6: 10117-2023-002
A7: Kunden-Nr: | B7: 10117
A8: Rechnungsdatum: | B8: 45027
C10: Rechnung über Honorare
A11: Für die nachfolgend aufgeführten Leistungen erlaube ich mir nach der Steuerberatervergütungsverordnung wie folgt abzurechnen:
A13: Pos. | B13: Datum | C13: §§ / Leistung | D13: Gebühren-satz | E13: Einheit | F13: Wert | G13: Gebühr | H13: Tabelle (A/B/C)
A14: 1 | B14: 45001 | C14: §24 / Erklärung zur Feststellung der Grundsteuer auf den 01.01.2022 - Neuer Weg 72, Frankfurt - Tabelle A | D14: 4/20 | E14: Stk. | F14: 341935.48 | G14: =IFERROR(IF(H14="",IFERROR(VALUE(LEFT(D14,FIND("/",D14)-1))/VALUE(MID(D14,FIND("/",D14)+1,100)),D14)*F14,IFERROR(VALUE(LEFT(D14,FIND("/",D14)-1))/VALUE(MID(D14,FIND("/",D14)+1,100)),D14)*VLOOKUP(F14,StBVV!$A:$D,MATCH(H14,StBVV!$B$3:$D$3,0)+1,TRUE)),IFERROR(VALUE(LEFT(D14,FIND("/",D14)-1))/VALUE(MID(D14,FIND("/",D14)+1,100)),D14)*F14) -> 585.2 | H14: A
A15: 2 | B15: 45027 | C15: §16 / Auslagenersatz für Post- und Telekommunikation | D15: 1 | E15: Stk. | F15: 20 | G15: =+D15*F15 -> 20
F16: Summe | G16: =SUM(G14:G15) -> 605.2
F17: Umsatzsteuer 19% | G17: =+G16*0.19 -> 114.988
F18: Bruttobetrag | G18: =SUM(G16:G17) -> 720.188

Sheet ESt Anlage V
A1: An:
A2: Klaus Walter
A3: Neuer Weg 72
A4: 60388 Frankfurt
A6: Rechnungs-Nr: | B6: 10117-2019-005
A7: Kunden-Nr: | B7: 10117
A8: Rechnungsdatum: | B8: 43690
C10: Rechnung über Honorare
A11: Für die nachfolgend aufgeführten Leistungen erlaube ich mir nach der Steuerberatervergütungsverordnung wie folgt abzurechnen:
A13: Pos. | B13: Datum | C13: §§ / Leistung | D13: Gebühren-satz | E13: Einheit | F13: Wert | G13: Gebühr | H13: Tabelle (A/B/C)
A14: 1 | B14: 43690 | C14: §27 / Ermittlung des Überschusses der Einnahmen über die Werbungskosten bei Vermietung - Oelsberg 2017 - Tabelle A | D14: 10/10 | E14: Stk. | F14: 8000 | G14: =IFERROR(IF(H14="",IFERROR(VALUE(LEFT(D14,FIND("/",D14)-1))/VALUE(MID(D14,FIND("/",D14)+1,100)),D14)*F14,IFERROR(VALUE(LEFT(D14,FIND("/",D14)-1))/VALUE(MID(D14,FIND("/",D14)+1,100)),D14)*VLOOKUP(F14,StBVV!$A:$D,MATCH(H14,StBVV!$B$3:$D$3,0)+1,TRUE)),IFERROR(VALUE(LEFT(D14,FIND("/",D14)-1))/VALUE(MID(D14,FIND("/",D14)+1,100)),D14)*F14) -> 514 | H14: A
A15: 2 | B15: 43690 | C15: §16 / Auslagenersatz für Post- und Telekommunikation | D15: 1 | E15: Stk. | F15: 20 | G15: =+D15*F15 -> 20
F16: Summe | G16: =SUM(G14:G15) -> 534
F17: Umsatzsteuer 19% | G17: =+G16*0.19 -> 101.46
F18: Bruttobetrag | G18: =SUM(G16:G17) -> 635.46

Sheet EÜR
A1: An:
A2: Klaus Walter
A3: Neuer Weg 72
A4: 60388 Frankfurt
A6: Rechnungs-Nr: | B6: 10117-2025-004
A7: Kunden-Nr: | B7: 10117
A8: Rechnungsdatum: | B8: 45807
C10: Rechnung über Honorare
A11: Für die nachfolgend aufgeführten Leistungen erlaube ich mir nach der Steuerberatervergütungsverordnung wie folgt abzurechnen:
A13: Pos. | B13: Datum | C13: §§ / Leistung | D13: Gebühren-satz | E13: Einheit | F13: Wert | G13: Gebühr | H13: Tabelle (A/B/C)
A14: 1 | B14: 45807 | C14: §25 / Einnahmenüberschussrechnung 2023 - Tabelle B | D14: 28/10 | E14: Stk. | F14: 39848.19 | G14: =IFERROR(IF(H14="",IFERROR(VALUE(LEFT(D14,FIND("/",D14)-1))/VALUE(MID(D14,FIND("/",D14)+1,100)),D14)*F14,IFERROR(VALUE(LEFT(D14,FIND("/",D14)-1))/VALUE(MID(D14,FIND("/",D14)+1,100)),D14)*VLOOKUP(F14,StBVV!$A:$D,MATCH(H14,StBVV!$B$3:$D$3,0)+1,TRUE)),IFERROR(VALUE(LEFT(D14,FIND("/",D14)-1))/VALUE(MID(D14,FIND("/",D14)+1,100)),D14)*F14) -> 736.4 | H14: B
A15: 2 | B15: 45807 | C15: §25 / Vorarbeiten bei der Ermittlung des Überschusses der Betriebseinnahmen über die Betriebsausgaben 2023 (Ermittlung fehlender Unterlagen, Einarbeitung nachgereichter Belege) | D15: 4 | E15: Stk. | F15: 95 | G15: =+D15*F15 -> 380
A16: 3 | B16: 45807 | C16: §24 / Umsatzsteuerjahreserklärung für 2023 - Tabelle A | D16: 6/10 | E16: Stk. | F16: 8000 | G16: =IFERROR(IF(H16="",IFERROR(VALUE(LEFT(D16,FIND("/",D16)-1))/VALUE(MID(D16,FIND("/",D16)+1,100)),D16)*F16,IFERROR(VALUE(LEFT(D16,FIND("/",D16)-1))/VALUE(MID(D16,FIND("/",D16)+1,100)),D16)*VLOOKUP(F16,StBVV!$A:$D,MATCH(H16,StBVV!$B$3:$D$3,0)+1,TRUE)),IFERROR(VALUE(LEFT(D16,FIND("/",D16)-1))/VALUE(MID(D16,FIND("/",D16)+1,100)),D16)*F16) -> 308.4 | H16: A
A17: 4 | B17: 45807 | C17: §16 / Auslagenersatz für Post- und Telekommunikation | D17: 1 | E17: Stk. | F17: 20 | G17: =+D17*F17 -> 20
F18: Summe | G18: =SUM(G14:G17) -> 1444.8
F19: Umsatzsteuer 19% | G19: =+G18*0.19 -> 274.512
F20: Bruttobetrag | G20: =SUM(G18:G19) -> 1719.312

Sheet DRV-Prüfung
A1: An:
A2: Roger Detroy
A3: Heerstraße 60
A4: 60488 Frankfurt
A6: Rechnungs-Nr: | B6: 60431-2024-005
A7: Kunden-Nr: | B7: 60431
A8: Rechnungsdatum: | B8: 45474
C10: Rechnung über Honorare
A11: Für die nachfolgend aufgeführten Leistungen erlaube ich mir nach der Steuerberatervergütungsverordnung wie folgt abzurechnen:
A13: Pos. | B13: Datum | C13: §§ / Leistung | D13: Gebühren-satz | E13: Einheit | F13: Wert | G13: Gebühr | H13: Tabelle (A/B/C)
A14: 1 | B14: 45474 | C14: §29 / Teilnahme an der Sozialversicherungsprüfung durch die DRV für 2020-2023 (Vorbereitung der Prüfung und Zusammenstellung von Unterlagen/Bereitstellung von DATEV-Lohnarchiv-CD-Daten am 08.05.2024 und am 20.06.2024; Abschluss der Prüfung durch Prüfung der Prüfungsschlussmitteilung am 01.07.2024) | D14: 4.5 | E14: h | F14: 120 | G14: =+D14*F14 -> 540
A15: 2 | B15: 45474 | C15: §16 / Auslagenersatz für Post- und Telekommunikation | D15: 1 | E15: Stk. | F15: 10 | G15: =+D15*F15 -> 10
F16: Summe | G16: =SUM(G14:G15) -> 550
F17: Umsatzsteuer 19% | G17: =+G16*0.19 -> 104.5
F18: Bruttobetrag | G18: =SUM(G16:G17) -> 654.5

Sheet ESt
A1: An:
A2: Klaus Walter
A3: Neuer Weg 72
A4: 60388 Frankfurt
A6: Rechnungs-Nr: | B6: 10117-2024-005
A7: Kunden-Nr: | B7: 10117
A8: Rechnungsdatum: | B8: 45471
C10: Rechnung über Honorare
A11: Für die nachfolgend aufgeführten Leistungen erlaube ich mir nach der Steuerberatervergütungsverordnung wie folgt abzurechnen:
A13: Pos. | B13: Datum | C13: §§ / Leistung | D13: Gebühren-satz | E13: Einheit | F13: Wert | G13: Gebühr | H13: Tabelle (A/B/C)
A14: 1 | B14: 45471 | C14: §24 / Einkommensteuererklärung ohne Ermittlung der einzelnen Einkünfte für 2022 - Tabelle A | D14: 4/10 | E14: Stk. | F14: 172921 | G14: =IFERROR(IF(H14="",IFERROR(VALUE(LEFT(D14,FIND("/",D14)-1))/VALUE(MID(D14,FIND("/",D14)+1,100)),D14)*F14,IFERROR(VALUE(LEFT(D14,FIND("/",D14)-1))/VALUE(MID(D14,FIND("/",D14)+1,100)),D14)*VLOOKUP(F14,StBVV!$A:$D,MATCH(H14,StBVV!$B$3:$D$3,0)+1,TRUE)),IFERROR(VALUE(LEFT(D14,FIND("/",D14)-1))/VALUE(MID(D14,FIND("/",D14)+1,100)),D14)*F14) -> 867.2 | H14: A
A15: 2 | B15: 45471 | C15: §27 / Ermittlung des Überschusses der Einnahmen über die Werbungskosten bei Vermietung Neuer Weg 72 für 2022 - Tabelle A | D15: 8/10 | E15: Stk. | F15: 8000 | G15: =IFERROR(IF(H15="",IFERROR(VALUE(LEFT(D15,FIND("/",D15)-1))/VALUE(MID(D15,FIND("/",D15)+1,100)),D15)*F15,IFERROR(VALUE(LEFT(D15,FIND("/",D15)-1))/VALUE(MID(D15,FIND("/",D15)+1,100)),D15)*VLOOKUP(F15,StBVV!$A:$D,MATCH(H15,StBVV!$B$3:$D$3,0)+1,TRUE)),IFERROR(VALUE(LEFT(D15,FIND("/",D15)-1))/VALUE(MID(D15,FIND("/",D15)+1,100)),D15)*F15) -> 411.2 | H15: A
A16: 3 | B16: 45471 | C16: §27 / Ermittlung des Überschusses der Einnahmen über die Werbungskosten bei Kapitalerträgen - Hr. Walter für 2022 - Tabelle A | D16: 3,5/10 | E16: Stk. | F16: 42873 | G16: =IFERROR(IF(H16="",IFERROR(VALUE(LEFT(D16,FIND("/",D16)-1))/VALUE(MID(D16,FIND("/",D16)+1,100)),D16)*F16,IFERROR(VALUE(LEFT(D16,FIND("/",D16)-1))/VALUE(MID(D16,FIND("/",D16)+1,100)),D16)*VLOOKUP(F16,StBVV!$A:$D,MATCH(H16,StBVV!$B$3:$D$3,0)+1,TRUE)),IFERROR(VALUE(LEFT(D16,FIND("/",D16)-1))/VALUE(MID(D16,FIND("/",D16)+1,100)),D16)*F16) -> 425.25 | H16: A
A17: 4 | B17: 45471 | C17: §27 / Ermittlung des Überschusses der Einnahmen über die Werbungskosten bei Kapitalerträgen - Fr. Nikulka für 2022 - Tabelle A | D17: 2/10 | E17: Stk. | F17: 8000 | G17: =IFERROR(IF(H17="",IFERROR(VALUE(LEFT(D17,FIND("/",D17)-1))/VALUE(MID(D17,FIND("/",D17)+1,100)),D17)*F17,IFERROR(VALUE(LEFT(D17,FIND("/",D17)-1))/VALUE(MID(D17,FIND("/",D17)+1,100)),D17)*VLOOKUP(F17,StBVV!$A:$D,MATCH(H17,StBVV!$B$3:$D$3,0)+1,TRUE)),IFERROR(VALUE(LEFT(D17,FIND("/",D17)-1))/VALUE(MID(D17,FIND("/",D17)+1,100)),D17)*F17) -> 102.8 | H17: A
A18: 5 | B18: 45471 | C18: §16 / Auslagenersatz für Post- und Telekommunikation | D18: 0 | E18: Stk. | F18: 252.21 | G18: 20
F19: Summe | G19: =SUM(G14:G18) -> 1826.45
F20: Umsatzsteuer 19% | G20: =+G19*0.19 -> 347.0255
F21: Bruttobetrag | G21: =SUM(G19:G20) -> 2173.4755

Sheet BP
